Workbook

Sheet FK_ÜRÜN_ÇEVRİM _DETAY
H1: PAZARTESİ | L1: SALI | P1: ÇARŞAMBA | T1: PERŞEMBE | X1: CUMA | AB1: CUMARTESİ
A2: Makine Adı | B2: 45936 | C2: 45937 | D2: 45938 | E2: 45939 | F2: 45940 | G2: 45941 | H2: 46020 | I2: Toplam Göz Sayısı (ad) | J2: Çalışan Göz Sayısı (ad) | K2: Çevrim Süresi (sn) | L2: 46007 | M2: Toplam Göz Sayısı (ad) | N2: Çalışan Göz Sayısı (ad) | O2: Çevrim Süresi (sn) | P2: 46008 | Q2: Toplam Göz Sayısı (ad) | R2: Çalışan Göz Sayısı (ad) | S2: Çevrim Süresi (sn) | T2: 46009 | U2: Toplam Göz Sayısı (ad) | V2: Çalışan Göz Sayısı (ad) | W2: Çevrim Süresi (sn) | X2: 46010 | Y2: Toplam Göz Sayısı (ad) | Z2: Çalışan Göz Sayısı (ad) | AA2: Çevrim Süresi (sn) | AB2: 46011 | AC2: Toplam Göz Sayısı (ad) | AD2: Çalışan Göz Sayısı (ad) | AE2: Çevrim Süresi (sn)
A3: 101 | B3: {=IFERROR(INDEX('[1]PROSES ENJEKSİYON'!$L:$L, MATCH(1,('[1]PROSES ENJEKSİYON'!$A:$A=$B$2)*('[1]PROSES ENJEKSİYON'!$F:$F=A3),0)), "")} | C3: {=IFERROR(INDEX('[1]PROSES ENJEKSİYON'!$L:$L,MATCH(1,('[1]PROSES ENJEKSİYON'!$A:$A=$C$2)*('[1]PROSES ENJEKSİYON'!$F:$F=A3),0)),"")} | D3: {=IFERROR(INDEX('[1]PROSES ENJEKSİYON'!$L:$L,MATCH(1,('[1]PROSES ENJEKSİYON'!$A:$A=$D$2)*('[1]PROSES ENJEKSİYON'!$F:$F=A3),0)),"")} | E3: {=IFERROR(INDEX('[1]PROSES ENJEKSİYON'!$L:$L,MATCH(1,('[1]PROSES ENJEKSİYON'!$A:$A=$E$2)*('[1]PROSES ENJEKSİYON'!$F:$F=A3),0)),"")} | F3: {=IFERROR(INDEX('[1]PROSES ENJEKSİYON'!$L:$L,MATCH(1,('[1]PROSES ENJEKSİYON'!$A:$A=$F$2)*('[1]PROSES ENJEKSİYON'!$F:$F=A3),0)),"")} | G3: {=IFERROR(INDEX('[1]PROSES ENJEKSİYON'!$L:$L,MATCH(1,('[1]PROSES ENJEKSİYON'!$A:$A=$G$2)*('[1]PROSES ENJEKSİYON'!$F:$F=A3),0)),"")} | H3: {=IFERROR(INDEX('[1]PROSES ENJEKSİYON'!$G:$G,MATCH(1,('[1]PROSES ENJEKSİYON'!$A:$A=$H$2)*('[1]PROSES ENJEKSİYON'!$F:$F=A3),0)),"")} -> PET0238-03 450ML SEFFAF UV 28MM CAKMA 33GR | I3: {=IFERROR(INDEX('[1]PROSES ENJEKSİYON'!$J:$J,MATCH(1,('[1]PROSES ENJEKSİYON'!$A:$A=$H$2)*('[1]PROSES ENJEKSİYON'!$F:$F=A3),0)),"")} -> 4 | J3: {=IFERROR(INDEX('[1]PROSES ENJEKSİYON'!$K:$K,MATCH(1,('[1]PROSES ENJEKSİYON'!$A:$A=$H$2)*('[1]PROSES ENJEKSİYON'!$F:$F=A3),0)),"")} -> 4 | K3: {=IFERROR(INDEX('[1]PROSES ENJEKSİYON'!$L:$L,MATCH(1,('[1]PROSES ENJEKSİYON'!$A:$A=$H$2)*('[1]PROSES ENJEKSİYON'!$F:$F=A3),0)),"")} -> 17.96 | L3: {=IFERROR(INDEX('[1]PROSES ENJEKSİYON'!$G:$G,MATCH(1,('[1]PROSES ENJEKSİYON'!$A:$A=$L$2)*('[1]PROSES ENJEKSİYON'!$F:$F=A3),0)),"")} | M3: {=IFERROR(INDEX('[1]PROSES ENJEKSİYON'!$J:$J,MATCH(1,('[1]PROSES ENJEKSİYON'!$A:$A=$L$2)*('[1]PROSES ENJEKSİYON'!$F:$F=A3),0)),"")} | N3: {=IFERROR(INDEX('[1]PROSES ENJEKSİYON'!$K:$K,MATCH(1,('[1]PROSES ENJEKSİYON'!$A:$A=$L$2)*('[1]PROSES ENJEKSİYON'!$F:$F=A3),0)),"")} | O3: {=IFERROR(INDEX('[1]PROSES ENJEKSİYON'!$L:$L,MATCH(1,('[1]PROSES ENJEKSİYON'!$A:$A=$L$2)*('[1]PROSES ENJEKSİYON'!$F:$F=A3),0)),"")} | P3: {=IFERROR(INDEX('[1]PROSES ENJEKSİYON'!$G:$G,MATCH(1,('[1]PROSES ENJEKSİYON'!$A:$A=$P$2)*('[1]PROSES ENJEKSİYON'!$F:$F=A3),0)),"")} | Q3: {=IFERROR(INDEX('[1]PROSES ENJEKSİYON'!$J:$J,MATCH(1,('[1]PROSES ENJEKSİYON'!$A:$A=$P$2)*('[1]PROSES ENJEKSİYON'!$F:$F=A3),0)),"")} | R3: {=IFERROR(INDEX('[1]PROSES ENJEKSİYON'!$K:$K,MATCH(1,('[1]PROSES ENJEKSİYON'!$A:$A=$P$2)*('[1]PROSES ENJEKSİYON'!$F:$F=A3),0)),"")} | S3: {=IFERROR(INDEX('[1]PROSES ENJEKSİYON'!$L:$L,MATCH(1,('[1]PROSES ENJEKSİYON'!$A:$A=$P$2)*('[1]PROSES ENJEKSİYON'!$F:$F=A3),0)),"")} | T3: {=IFERROR(INDEX('[1]PROSES ENJEKSİYON'!$G:$G,MATCH(1,('[1]PROSES ENJEKSİYON'!$A:$A=$T$2)*('[1]PROSES ENJEKSİYON'!$F:$F=A3),0)),"")} -> PET0003-01 500ML SEFFAF SEFFAF 28MM YIVLI 29GR | U3: {=IFERROR(INDEX('[1]PROSES ENJEKSİYON'!$J:$J,MATCH(1,('[1]PROSES ENJEKSİYON'!$A:$A=$T$2)*('[1]PROSES ENJEKSİYON'!$F:$F=A3),0)),"")} -> 4 | V3: {=IFERROR(INDEX('[1]PROSES ENJEKSİYON'!$K:$K,MATCH(1,('[1]PROSES ENJEKSİYON'!$A:$A=$T$2)*('[1]PROSES ENJEKSİYON'!$F:$F=A3),0)),"")} -> 4 | W3: {=IFERROR(INDEX('[1]PROSES ENJEKSİYON'!$L:$L,MATCH(1,('[1]PROSES ENJEKSİYON'!$A:$A=$T$2)*('[1]PROSES ENJEKSİYON'!$F:$F=A3),0)),"")} -> 13.2 | X3: {=IFERROR(INDEX('[1]PROSES ENJEKSİYON'!$G:$G,MATCH(1,('[1]PROSES ENJEKSİYON'!$A:$A=$X$2)*('[1]PROSES ENJEKSİYON'!$F:$F=A3),0)),"")} | Y3: {=IFERROR(INDEX('[1]PROSES ENJEKSİYON'!$J:$J,MATCH(1,('[1]PROSES ENJEKSİYON'!$A:$A=$X$2)*('[1]PROSES ENJEKSİYON'!$F:$F=A3),0)),"")} | Z3: {=IFERROR(INDEX('[1]PROSES ENJEKSİYON'!$K:$K,MATCH(1,('[1]PROSES ENJEKSİYON'!$A:$A=$X$2)*('[1]PROSES ENJEKSİYON'!$F:$F=A3),0)),"")} | AA3: {=IFERROR(INDEX('[1]PROSES ENJEKSİYON'!$L:$L,MATCH(1,('[1]PROSES ENJEKSİYON'!$A:$A=$X$2)*('[1]PROSES ENJEKSİYON'!$F:$F=A3),0)),"")} | AB3: {=IFERROR(INDEX('[1]PROSES ENJEKSİYON'!$G:$G,MATCH(1,('[1]PROSES ENJEKSİYON'!$A:$A=$AB$2)*('[1]PROSES ENJEKSİYON'!$F:$F=A3),0)),"")} | AC3: {=IFERROR(INDEX('[1]PROSES ENJEKSİYON'!$J:$J,MATCH(1,('[1]PROSES ENJEKSİYON'!$A:$A=$AB$2)*('[1]PROSES ENJEKSİYON'!$F:$F=M3),0)),"")} | AD3: {=IFERROR(INDEX('[1]PROSES ENJEKSİYON'!$K:$K,MATCH(1,('[1]PROSES ENJEKSİYON'!$A:$A=$AD$2)*('[1]PROSES ENJEKSİYON'!$F:$F=M3),0)),"")} | AE3: {=IFERROR(INDEX('[1]PROSES ENJEKSİYON'!$L:$L,MATCH(1,('[1]PROSES ENJEKSİYON'!$A:$A=$AB$2)*('[1]PROSES ENJEKSİYON'!$F:$F=A3),0)),"")}
A4: 102 | B4: {=IFERROR(INDEX('[1]PROSES ENJEKSİYON'!$L:$L, MATCH(1,('[1]PROSES ENJEKSİYON'!$A:$A=$B$2)*('[1]PROSES ENJEKSİYON'!$F:$F=A4),0)), "")} | C4: {=IFERROR(INDEX('[1]PROSES ENJEKSİYON'!$L:$L,MATCH(1,('[1]PROSES ENJEKSİYON'!$A:$A=$C$2)*('[1]PROSES ENJEKSİYON'!$F:$F=A4),0)),"")} | D4: {=IFERROR(INDEX('[1]PROSES ENJEKSİYON'!$L:$L,MATCH(1,('[1]PROSES ENJEKSİYON'!$A:$A=$D$2)*('[1]PROSES ENJEKSİYON'!$F:$F=A4),0)),"")} | E4: {=IFERROR(INDEX('[1]PROSES ENJEKSİYON'!$L:$L,MATCH(1,('[1]PROSES ENJEKSİYON'!$A:$A=$E$2)*('[1]PROSES ENJEKSİYON'!$F:$F=A4),0)),"")} | F4: {=IFERROR(INDEX('[1]PROSES ENJEKSİYON'!$L:$L,MATCH(1,('[1]PROSES ENJEKSİYON'!$A:$A=$F$2)*('[1]PROSES ENJEKSİYON'!$F:$F=A4),0)),"")} | G4: {=IFERROR(INDEX('[1]PROSES ENJEKSİYON'!$L:$L,MATCH(1,('[1]PROSES ENJEKSİYON'!$A:$A=$G$2)*('[1]PROSES ENJEKSİYON'!$F:$F=A4),0)),"")} | H4: {=IFERROR(INDEX('[1]PROSES ENJEKSİYON'!$G:$G,MATCH(1,('[1]PROSES ENJEKSİYON'!$A:$A=$H$2)*('[1]PROSES ENJEKSİYON'!$F:$F=A4),0)),"")} -> PET0011-03 150ML SEFFAF SEFFAF 24MM YIVLI 20GR | I4: {=IFERROR(INDEX('[1]PROSES ENJEKSİYON'!$J:$J,MATCH(1,('[1]PROSES ENJEKSİYON'!$A:$A=$H$2)*('[1]PROSES ENJEKSİYON'!$F:$F=A4),0)),"")} -> 9 | J4: {=IFERROR(INDEX('[1]PROSES ENJEKSİYON'!$K:$K,MATCH(1,('[1]PROSES ENJEKSİYON'!$A:$A=$H$2)*('[1]PROSES ENJEKSİYON'!$F:$F=A4),0)),"")} -> 8 | K4: {=IFERROR(INDEX('[1]PROSES ENJEKSİYON'!$L:$L,MATCH(1,('[1]PROSES ENJEKSİYON'!$A:$A=$H$2)*('[1]PROSES ENJEKSİYON'!$F:$F=A4),0)),"")} -> 12.2 | L4: {=IFERROR(INDEX('[1]PROSES ENJEKSİYON'!$G:$G,MATCH(1,('[1]PROSES ENJEKSİYON'!$A:$A=$L$2)*('[1]PROSES ENJEKSİYON'!$F:$F=A4),0)),"")} | M4: {=IFERROR(INDEX('[1]PROSES ENJEKSİYON'!$J:$J,MATCH(1,('[1]PROSES ENJEKSİYON'!$A:$A=$L$2)*('[1]PROSES ENJEKSİYON'!$F:$F=A4),0)),"")} | N4: {=IFERROR(INDEX('[1]PROSES ENJEKSİYON'!$K:$K,MATCH(1,('[1]PROSES ENJEKSİYON'!$A:$A=$L$2)*('[1]PROSES ENJEKSİYON'!$F:$F=A4),0)),"")} | O4: {=IFERROR(INDEX('[1]PROSES ENJEKSİYON'!$L:$L,MATCH(1,('[1]PROSES ENJEKSİYON'!$A:$A=$L$2)*('[1]PROSES ENJEKSİYON'!$F:$F=A4),0)),"")} | P4: {=IFERROR(INDEX('[1]PROSES ENJEKSİYON'!$G:$G,MATCH(1,('[1]PROSES ENJEKSİYON'!$A:$A=$P$2)*('[1]PROSES ENJEKSİYON'!$F:$F=A4),0)),"")} | Q4: {=IFERROR(INDEX('[1]PROSES ENJEKSİYON'!$J:$J,MATCH(1,('[1]PROSES ENJEKSİYON'!$A:$A=$P$2)*('[1]PROSES ENJEKSİYON'!$F:$F=A4),0)),"")} | R4: {=IFERROR(INDEX('[1]PROSES ENJEKSİYON'!$K:$K,MATCH(1,('[1]PROSES ENJEKSİYON'!$A:$A=$P$2)*('[1]PROSES ENJEKSİYON'!$F:$F=A4),0)),"")} | S4: {=IFERROR(INDEX('[1]PROSES ENJEKSİYON'!$L:$L,MATCH(1,('[1]PROSES ENJEKSİYON'!$A:$A=$P$2)*('[1]PROSES ENJEKSİYON'!$F:$F=A4),0)),"")} | T4: {=IFERROR(INDEX('[1]PROSES ENJEKSİYON'!$G:$G,MATCH(1,('[1]PROSES ENJEKSİYON'!$A:$A=$T$2)*('[1]PROSES ENJEKSİYON'!$F:$F=A4),0)),"")} | U4: {=IFERROR(INDEX('[1]PROSES ENJEKSİYON'!$J:$J,MATCH(1,('[1]PROSES ENJEKSİYON'!$A:$A=$T$2)*('[1]PROSES ENJEKSİYON'!$F:$F=A4),0)),"")} | V4: {=IFERROR(INDEX('[1]PROSES ENJEKSİYON'!$K:$K,MATCH(1,('[1]PROSES ENJEKSİYON'!$A:$A=$T$2)*('[1]PROSES ENJEKSİYON'!$F:$F=A4),0)),"")} | W4: {=IFERROR(INDEX('[1]PROSES ENJEKSİYON'!$L:$L,MATCH(1,('[1]PROSES ENJEKSİYON'!$A:$A=$T$2)*('[1]PROSES ENJEKSİYON'!$F:$F=A4),0)),"")} | X4: {=IFERROR(INDEX('[1]PROSES ENJEKSİYON'!$G:$G,MATCH(1,('[1]PROSES ENJEKSİYON'!$A:$A=$X$2)*('[1]PROSES ENJEKSİYON'!$F:$F=A4),0)),"")} | Y4: {=IFERROR(INDEX('[1]PROSES ENJEKSİYON'!$J:$J,MATCH(1,('[1]PROSES ENJEKSİYON'!$A:$A=$X$2)*('[1]PROSES ENJEKSİYON'!$F:$F=A4),0)),"")} | Z4: {=IFERROR(INDEX('[1]PROSES ENJEKSİYON'!$K:$K,MATCH(1,('[1]PROSES ENJEKSİYON'!$A:$A=$X$2)*('[1]PROSES ENJEKSİYON'!$F:$F=A4),0)),"")} | AA4: {=IFERROR(INDEX('[1]PROSES ENJEKSİYON'!$L:$L,MATCH(1,('[1]PROSES ENJEKSİYON'!$A:$A=$X$2)*('[1]PROSES ENJEKSİYON'!$F:$F=A4),0)),"")} | AB4: {=IFERROR(INDEX('[1]PROSES ENJEKSİYON'!$G:$G,MATCH(1,('[1]PROSES ENJEKSİYON'!$A:$A=$AB$2)*('[1]PROSES ENJEKSİYON'!$F:$F=A4),0)),"")} | AC4: {=IFERROR(INDEX('[1]PROSES ENJEKSİYON'!$J:$J,MATCH(1,('[1]PROSES ENJEKSİYON'!$A:$A=$AB$2)*('[1]PROSES ENJEKSİYON'!$F:$F=M4),0)),"")} | AD4: {=IFERROR(INDEX('[1]PROSES ENJEKSİYON'!$K:$K,MATCH(1,('[1]PROSES ENJEKSİYON'!$A:$A=$AD$2)*('[1]PROSES ENJEKSİYON'!$F:$F=M4),0)),"")} | AE4: {=IFERROR(INDEX('[1]PROSES ENJEKSİYON'!$L:$L,MATCH(1,('[1]PROSES ENJEKSİYON'!$A:$A=$AB$2)*('[1]PROSES ENJEKSİYON'!$F:$F=A4),0)),"")}
A5: 103 | B5: {=IFERROR(INDEX('[1]PROSES ENJEKSİYON'!$L:$L, MATCH(1,('[1]PROSES ENJEKSİYON'!$A:$A=$B$2)*('[1]PROSES ENJEKSİYON'!$F:$F=A5),0)), "")} | C5: {=IFERROR(INDEX('[1]PROSES ENJEKSİYON'!$L:$L,MATCH(1,('[1]PROSES ENJEKSİYON'!$A:$A=$C$2)*('[1]PROSES ENJEKSİYON'!$F:$F=A5),0)),"")} | D5: {=IFERROR(INDEX('[1]PROSES ENJEKSİYON'!$L:$L,MATCH(1,('[1]PROSES ENJEKSİYON'!$A:$A=$D$2)*('[1]PROSES ENJEKSİYON'!$F:$F=A5),0)),"")} | E5: {=IFERROR(INDEX('[1]PROSES ENJEKSİYON'!$L:$L,MATCH(1,('[1]PROSES ENJEKSİYON'!$A:$A=$E$2)*('[1]PROSES ENJEKSİYON'!$F:$F=A5),0)),"")} | F5: {=IFERROR(INDEX('[1]PROSES ENJEKSİYON'!$L:$L,MATCH(1,('[1]PROSES ENJEKSİYON'!$A:$A=$F$2)*('[1]PROSES ENJEKSİYON'!$F:$F=A5),0)),"")} | G5: {=IFERROR(INDEX('[1]PROSES ENJEKSİYON'!$L:$L,MATCH(1,('[1]PROSES ENJEKSİYON'!$A:$A=$G$2)*('[1]PROSES ENJEKSİYON'!$F:$F=A5),0)),"")} | H5: {=IFERROR(INDEX('[1]PROSES ENJEKSİYON'!$G:$G,MATCH(1,('[1]PROSES ENJEKSİYON'!$A:$A=$H$2)*('[1]PROSES ENJEKSİYON'!$F:$F=A5),0)),"")} -> PET0005-01 700ML SEFFAF SARI 28MM YIVLI 40GR | I5: {=IFERROR(INDEX('[1]PROSES ENJEKSİYON'!$J:$J,MATCH(1,('[1]PROSES ENJEKSİYON'!$A:$A=$H$2)*('[1]PROSES ENJEKSİYON'!$F:$F=A5),0)),"")} -> 5 | J5: {=IFERROR(INDEX('[1]PROSES ENJEKSİYON'!$K:$K,MATCH(1,('[1]PROSES ENJEKSİYON'!$A:$A=$H$2)*('[1]PROSES ENJEKSİYON'!$F:$F=A5),0)),"")} -> 5 | K5: {=IFERROR(INDEX('[1]PROSES ENJEKSİYON'!$L:$L,MATCH(1,('[1]PROSES ENJEKSİYON'!$A:$A=$H$2)*('[1]PROSES ENJEKSİYON'!$F:$F=A5),0)),"")} -> 15.59 | L5: {=IFERROR(INDEX('[1]PROSES ENJEKSİYON'!$G:$G,MATCH(1,('[1]PROSES ENJEKSİYON'!$A:$A=$L$2)*('[1]PROSES ENJEKSİYON'!$F:$F=A5),0)),"")} | M5: {=IFERROR(INDEX('[1]PROSES ENJEKSİYON'!$J:$J,MATCH(1,('[1]PROSES ENJEKSİYON'!$A:$A=$L$2)*('[1]PROSES ENJEKSİYON'!$F:$F=A5),0)),"")} | N5: {=IFERROR(INDEX('[1]PROSES ENJEKSİYON'!$K:$K,MATCH(1,('[1]PROSES ENJEKSİYON'!$A:$A=$L$2)*('[1]PROSES ENJEKSİYON'!$F:$F=A5),0)),"")} | O5: {=IFERROR(INDEX('[1]PROSES ENJEKSİYON'!$L:$L,MATCH(1,('[1]PROSES ENJEKSİYON'!$A:$A=$L$2)*('[1]PROSES ENJEKSİYON'!$F:$F=A5),0)),"")} | P5: {=IFERROR(INDEX('[1]PROSES ENJEKSİYON'!$G:$G,MATCH(1,('[1]PROSES ENJEKSİYON'!$A:$A=$P$2)*('[1]PROSES ENJEKSİYON'!$F:$F=A5),0)),"")} -> MM-PET0005-03-028Y-040 - PET0005-03 700ML OPAK SARI 28MM YIVLI 40GR | Q5: {=IFERROR(INDEX('[1]PROSES ENJEKSİYON'!$J:$J,MATCH(1,('[1]PROSES ENJEKSİYON'!$A:$A=$P$2)*('[1]PROSES ENJEKSİYON'!$F:$F=A5),0)),"")} -> 5 | R5: {=IFERROR(INDEX('[1]PROSES ENJEKSİYON'!$K:$K,MATCH(1,('[1]PROSES ENJEKSİYON'!$A:$A=$P$2)*('[1]PROSES ENJEKSİYON'!$F:$F=A5),0)),"")} -> 5 | S5: {=IFERROR(INDEX('[1]PROSES ENJEKSİYON'!$L:$L,MATCH(1,('[1]PROSES ENJEKSİYON'!$A:$A=$P$2)*('[1]PROSES ENJEKSİYON'!$F:$F=A5),0)),"")} -> 15.37 | T5: {=IFERROR(INDEX('[1]PROSES ENJEKSİYON'!$G:$G,MATCH(1,('[1]PROSES ENJEKSİYON'!$A:$A=$T$2)*('[1]PROSES ENJEKSİYON'!$F:$F=A5),0)),"")} -> PET0005-01 700ML SEFFAF SARI 28MM YIVLI 40GR | U5: {=IFERROR(INDEX('[1]PROSES ENJEKSİYON'!$J:$J,MATCH(1,('[1]PROSES ENJEKSİYON'!$A:$A=$T$2)*('[1]PROSES ENJEKSİYON'!$F:$F=A5),0)),"")} -> 5 | V5: {=IFERROR(INDEX('[1]PROSES ENJEKSİYON'!$K:$K,MATCH(1,('[1]PROSES ENJEKSİYON'!$A:$A=$T$2)*('[1]PROSES ENJEKSİYON'!$F:$F=A5),0)),"")} -> 5 | W5: {=IFERROR(INDEX('[1]PROSES ENJEKSİYON'!$L:$L,MATCH(1,('[1]PROSES ENJEKSİYON'!$A:$A=$T$2)*('[1]PROSES ENJEKSİYON'!$F:$F=A5),0)),"")} -> 15.52 | X5: {=IFERROR(INDEX('[1]PROSES ENJEKSİYON'!$G:$G,MATCH(1,('[1]PROSES ENJEKSİYON'!$A:$A=$X$2)*('[1]PROSES ENJEKSİYON'!$F:$F=A5),0)),"")} | Y5: {=IFERROR(INDEX('[1]PROSES ENJEKSİYON'!$J:$J,MATCH(1,('[1]PROSES ENJEKSİYON'!$A:$A=$X$2)*('[1]PROSES ENJEKSİYON'!$F:$F=A5),0)),"")} | Z5: {=IFERROR(INDEX('[1]PROSES ENJEKSİYON'!$K:$K,MATCH(1,('[1]PROSES ENJEKSİYON'!$A:$A=$X$2)*('[1]PROSES ENJEKSİYON'!$F:$F=A5),0)),"")} | AA5: {=IFERROR(INDEX('[1]PROSES ENJEKSİYON'!$L:$L,MATCH(1,('[1]PROSES ENJEKSİYON'!$A:$A=$X$2)*('[1]PROSES ENJEKSİYON'!$F:$F=A5),0)),"")} | AB5: {=IFERROR(INDEX('[1]PROSES ENJEKSİYON'!$G:$G,MATCH(1,('[1]PROSES ENJEKSİYON'!$A:$A=$AB$2)*('[1]PROSES ENJEKSİYON'!$F:$F=A5),0)),"")} | AC5: {=IFERROR(INDEX('[1]PROSES ENJEKSİYON'!$J:$J,MATCH(1,('[1]PROSES ENJEKSİYON'!$A:$A=$AB$2)*('[1]PROSES ENJEKSİYON'!$F:$F=M5),0)),"")} | AD5: {=IFERROR(INDEX('[1]PROSES ENJEKSİYON'!$K:$K,MATCH(1,('[1]PROSES ENJEKSİYON'!$A:$A=$AD$2)*('[1]PROSES ENJEKSİYON'!$F:$F=M5),0)),"")} | AE5: {=IFERROR(INDEX('[1]PROSES ENJEKSİYON'!$L:$L,MATCH(1,('[1]PROSES ENJEKSİYON'!$A:$A=$AB$2)*('[1]PROSES ENJEKSİYON'!$F:$F=A5),0)),"")}
A6: 104 | B6: {=IFERROR(INDEX('[1]PROSES ENJEKSİYON'!$L:$L, MATCH(1,('[1]PROSES ENJEKSİYON'!$A:$A=$B$2)*('[1]PROSES ENJEKSİYON'!$F:$F=A6),0)), "")} | C6: {=IFERROR(INDEX('[1]PROSES ENJEKSİYON'!$L:$L,MATCH(1,('[1]PROSES ENJEKSİYON'!$A:$A=$C$2)*('[1]PROSES ENJEKSİYON'!$F:$F=A6),0)),"")} | D6: {=IFERROR(INDEX('[1]PROSES ENJEKSİYON'!$L:$L,MATCH(1,('[1]PROSES ENJEKSİYON'!$A:$A=$D$2)*('[1]PROSES ENJEKSİYON'!$F:$F=A6),0)),"")} | E6: {=IFERROR(INDEX('[1]PROSES ENJEKSİYON'!$L:$L,MATCH(1,('[1]PROSES ENJEKSİYON'!$A:$A=$E$2)*('[1]PROSES ENJEKSİYON'!$F:$F=A6),0)),"")} | F6: {=IFERROR(INDEX('[1]PROSES ENJEKSİYON'!$L:$L,MATCH(1,('[1]PROSES ENJEKSİYON'!$A:$A=$F$2)*('[1]PROSES ENJEKSİYON'!$F:$F=A6),0)),"")} | G6: {=IFERROR(INDEX('[1]PROSES ENJEKSİYON'!$L:$L,MATCH(1,('[1]PROSES ENJEKSİYON'!$A:$A=$G$2)*('[1]PROSES ENJEKSİYON'!$F:$F=A6),0)),"")} | H6: {=IFERROR(INDEX('[1]PROSES ENJEKSİYON'!$G:$G,MATCH(1,('[1]PROSES ENJEKSİYON'!$A:$A=$H$2)*('[1]PROSES ENJEKSİYON'!$F:$F=A6),0)),"")} -> PET0007-08 400ML OPAK YESIL 28MM YIVLI 25GR | I6: {=IFERROR(INDEX('[1]PROSES ENJEKSİYON'!$J:$J,MATCH(1,('[1]PROSES ENJEKSİYON'!$A:$A=$H$2)*('[1]PROSES ENJEKSİYON'!$F:$F=A6),0)),"")} -> 6 | J6: {=IFERROR(INDEX('[1]PROSES ENJEKSİYON'!$K:$K,MATCH(1,('[1]PROSES ENJEKSİYON'!$A:$A=$H$2)*('[1]PROSES ENJEKSİYON'!$F:$F=A6),0)),"")} -> 5 | K6: {=IFERROR(INDEX('[1]PROSES ENJEKSİYON'!$L:$L,MATCH(1,('[1]PROSES ENJEKSİYON'!$A:$A=$H$2)*('[1]PROSES ENJEKSİYON'!$F:$F=A6),0)),"")} -> 15.92 | L6: {=IFERROR(INDEX('[1]PROSES ENJEKSİYON'!$G:$G,MATCH(1,('[1]PROSES ENJEKSİYON'!$A:$A=$L$2)*('[1]PROSES ENJEKSİYON'!$F:$F=A6),0)),"")} | M6: {=IFERROR(INDEX('[1]PROSES ENJEKSİYON'!$J:$J,MATCH(1,('[1]PROSES ENJEKSİYON'!$A:$A=$L$2)*('[1]PROSES ENJEKSİYON'!$F:$F=A6),0)),"")} | N6: {=IFERROR(INDEX('[1]PROSES ENJEKSİYON'!$K:$K,MATCH(1,('[1]PROSES ENJEKSİYON'!$A:$A=$L$2)*('[1]PROSES ENJEKSİYON'!$F:$F=A6),0)),"")} | O6: {=IFERROR(INDEX('[1]PROSES ENJEKSİYON'!$L:$L,MATCH(1,('[1]PROSES ENJEKSİYON'!$A:$A=$L$2)*('[1]PROSES ENJEKSİYON'!$F:$F=A6),0)),"")} | P6: {=IFERROR(INDEX('[1]PROSES ENJEKSİYON'!$G:$G,MATCH(1,('[1]PROSES ENJEKSİYON'!$A:$A=$P$2)*('[1]PROSES ENJEKSİYON'!$F:$F=A6),0)),"")} -> MM-PET0166-02-028Y-025 - PET0166-02 400ML SEFFAF SEFFAF 28MM YIVLI 25GR | Q6: {=IFERROR(INDEX('[1]PROSES ENJEKSİYON'!$J:$J,MATCH(1,('[1]PROSES ENJEKSİYON'!$A:$A=$P$2)*('[1]PROSES ENJEKSİYON'!$F:$F=A6),0)),"")} -> 6 | R6: {=IFERROR(INDEX('[1]PROSES ENJEKSİYON'!$K:$K,MATCH(1,('[1]PROSES ENJEKSİYON'!$A:$A=$P$2)*('[1]PROSES ENJEKSİYON'!$F:$F=A6),0)),"")} -> 6 | S6: {=IFERROR(INDEX('[1]PROSES ENJEKSİYON'!$L:$L,MATCH(1,('[1]PROSES ENJEKSİYON'!$A:$A=$P$2)*('[1]PROSES ENJEKSİYON'!$F:$F=A6),0)),"")} -> 13.4 | T6: {=IFERROR(INDEX('[1]PROSES ENJEKSİYON'!$G:$G,MATCH(1,('[1]PROSES ENJEKSİYON'!$A:$A=$T$2)*('[1]PROSES ENJEKSİYON'!$F:$F=A6),0)),"")} | U6: {=IFERROR(INDEX('[1]PROSES ENJEKSİYON'!$J:$J,MATCH(1,('[1]PROSES ENJEKSİYON'!$A:$A=$T$2)*('[1]PROSES ENJEKSİYON'!$F:$F=A6),0)),"")} | V6: {=IFERROR(INDEX('[1]PROSES ENJEKSİYON'!$K:$K,MATCH(1,('[1]PROSES ENJEKSİYON'!$A:$A=$T$2)*('[1]PROSES ENJEKSİYON'!$F:$F=A6),0)),"")} | W6: {=IFERROR(INDEX('[1]PROSES ENJEKSİYON'!$L:$L,MATCH(1,('[1]PROSES ENJEKSİYON'!$A:$A=$T$2)*('[1]PROSES ENJEKSİYON'!$F:$F=A6),0)),"")} | X6: {=IFERROR(INDEX('[1]PROSES ENJEKSİYON'!$G:$G,MATCH(1,('[1]PROSES ENJEKSİYON'!$A:$A=$X$2)*('[1]PROSES ENJEKSİYON'!$F:$F=A6),0)),"")} | Y6: {=IFERROR(INDEX('[1]PROSES ENJEKSİYON'!$J:$J,MATCH(1,('[1]PROSES ENJEKSİYON'!$A:$A=$X$2)*('[1]PROSES ENJEKSİYON'!$F:$F=A6),0)),"")} | Z6: {=IFERROR(INDEX('[1]PROSES ENJEKSİYON'!$K:$K,MATCH(1,('[1]PROSES ENJEKSİYON'!$A:$A=$X$2)*('[1]PROSES ENJEKSİYON'!$F:$F=A6),0)),"")} | AA6: {=IFERROR(INDEX('[1]PROSES ENJEKSİYON'!$L:$L,MATCH(1,('[1]PROSES ENJEKSİYON'!$A:$A=$X$2)*('[1]PROSES ENJEKSİYON'!$F:$F=A6),0)),"")} | AB6: {=IFERROR(INDEX('[1]PROSES ENJEKSİYON'!$G:$G,MATCH(1,('[1]PROSES ENJEKSİYON'!$A:$A=$AB$2)*('[1]PROSES ENJEKSİYON'!$F:$F=A6),0)),"")} | AC6: {=IFERROR(INDEX('[1]PROSES ENJEKSİYON'!$J:$J,MATCH(1,('[1]PROSES ENJEKSİYON'!$A:$A=$AB$2)*('[1]PROSES ENJEKSİYON'!$F:$F=M6),0)),"")} | AD6: {=IFERROR(INDEX('[1]PROSES ENJEKSİYON'!$K:$K,MATCH(1,('[1]PROSES ENJEKSİYON'!$A:$A=$AD$2)*('[1]PROSES ENJEKSİYON'!$F:$F=M6),0)),"")} | AE6: {=IFERROR(INDEX('[1]PROSES ENJEKSİYON'!$L:$L,MATCH(1,('[1]PROSES ENJEKSİYON'!$A:$A=$AB$2)*('[1]PROSES ENJEKSİYON'!$F:$F=A6),0)),"")}
A7: 161 | B7: {=IFERROR(INDEX('[1]PROSES ENJEKSİYON'!$L:$L, MATCH(1,('[1]PROSES ENJEKSİYON'!$A:$A=$B$2)*('[1]PROSES ENJEKSİYON'!$F:$F=A7),0)), "")} | C7: {=IFERROR(INDEX('[1]PROSES ENJEKSİYON'!$L:$L,MATCH(1,('[1]PROSES ENJEKSİYON'!$A:$A=$C$2)*('[1]PROSES ENJEKSİYON'!$F:$F=A7),0)),"")} | D7: {=IFERROR(INDEX('[1]PROSES ENJEKSİYON'!$L:$L,MATCH(1,('[1]PROSES ENJEKSİYON'!$A:$A=$D$2)*('[1]PROSES ENJEKSİYON'!$F:$F=A7),0)),"")} | E7: {=IFERROR(INDEX('[1]PROSES ENJEKSİYON'!$L:$L,MATCH(1,('[1]PROSES ENJEKSİYON'!$A:$A=$E$2)*('[1]PROSES ENJEKSİYON'!$F:$F=A7),0)),"")} | F7: {=IFERROR(INDEX('[1]PROSES ENJEKSİYON'!$L:$L,MATCH(1,('[1]PROSES ENJEKSİYON'!$A:$A=$F$2)*('[1]PROSES ENJEKSİYON'!$F:$F=A7),0)),"")} | G7: {=IFERROR(INDEX('[1]PROSES ENJEKSİYON'!$L:$L,MATCH(1,('[1]PROSES ENJEKSİYON'!$A:$A=$G$2)*('[1]PROSES ENJEKSİYON'!$F:$F=A7),0)),"")} | H7: {=IFERROR(INDEX('[1]PROSES ENJEKSİYON'!$G:$G,MATCH(1,('[1]PROSES ENJEKSİYON'!$A:$A=$H$2)*('[1]PROSES ENJEKSİYON'!$F:$F=A7),0)),"")} -> PET0181-02 960ML OPAK SARI 38MM YIVLI 47GR | I7: {=IFERROR(INDEX('[1]PROSES ENJEKSİYON'!$J:$J,MATCH(1,('[1]PROSES ENJEKSİYON'!$A:$A=$H$2)*('[1]PROSES ENJEKSİYON'!$F:$F=A7),0)),"")} -> 6 | J7: {=IFERROR(INDEX('[1]PROSES ENJEKSİYON'!$K:$K,MATCH(1,('[1]PROSES ENJEKSİYON'!$A:$A=$H$2)*('[1]PROSES ENJEKSİYON'!$F:$F=A7),0)),"")} -> 6 | K7: {=IFERROR(INDEX('[1]PROSES ENJEKSİYON'!$L:$L,MATCH(1,('[1]PROSES ENJEKSİYON'!$A:$A=$H$2)*('[1]PROSES ENJEKSİYON'!$F:$F=A7),0)),"")} -> 22.51 | L7: {=IFERROR(INDEX('[1]PROSES ENJEKSİYON'!$G:$G,MATCH(1,('[1]PROSES ENJEKSİYON'!$A:$A=$L$2)*('[1]PROSES ENJEKSİYON'!$F:$F=A7),0)),"")} | M7: {=IFERROR(INDEX('[1]PROSES ENJEKSİYON'!$J:$J,MATCH(1,('[1]PROSES ENJEKSİYON'!$A:$A=$L$2)*('[1]PROSES ENJEKSİYON'!$F:$F=A7),0)),"")} | N7: {=IFERROR(INDEX('[1]PROSES ENJEKSİYON'!$K:$K,MATCH(1,('[1]PROSES ENJEKSİYON'!$A:$A=$L$2)*('[1]PROSES ENJEKSİYON'!$F:$F=A7),0)),"")} | O7: {=IFERROR(INDEX('[1]PROSES ENJEKSİYON'!$L:$L,MATCH(1,('[1]PROSES ENJEKSİYON'!$A:$A=$L$2)*('[1]PROSES ENJEKSİYON'!$F:$F=A7),0)),"")} | P7: {=IFERROR(INDEX('[1]PROSES ENJEKSİYON'!$G:$G,MATCH(1,('[1]PROSES ENJEKSİYON'!$A:$A=$P$2)*('[1]PROSES ENJEKSİYON'!$F:$F=A7),0)),"")} -> MM-PET0181-03-038Y-047 - PET0181-03 960ML OPAK KIRMIZI 38MM YIVLI 47GR | Q7: {=IFERROR(INDEX('[1]PROSES ENJEKSİYON'!$J:$J,MATCH(1,('[1]PROSES ENJEKSİYON'!$A:$A=$P$2)*('[1]PROSES ENJEKSİYON'!$F:$F=A7),0)),"")} -> 2 | R7: {=IFERROR(INDEX('[1]PROSES ENJEKSİYON'!$K:$K,MATCH(1,('[1]PROSES ENJEKSİYON'!$A:$A=$P$2)*('[1]PROSES ENJEKSİYON'!$F:$F=A7),0)),"")} -> 2 | S7: {=IFERROR(INDEX('[1]PROSES ENJEKSİYON'!$L:$L,MATCH(1,('[1]PROSES ENJEKSİYON'!$A:$A=$P$2)*('[1]PROSES ENJEKSİYON'!$F:$F=A7),0)),"")} -> 22.5 | T7: {=IFERROR(INDEX('[1]PROSES ENJEKSİYON'!$G:$G,MATCH(1,('[1]PROSES ENJEKSİYON'!$A:$A=$T$2)*('[1]PROSES ENJEKSİYON'!$F:$F=A7),0)),"")} -> PET0181-03 960ML OPAK KIRMIZI 38MM YIVLI 47GR | U7: {=IFERROR(INDEX('[1]PROSES ENJEKSİYON'!$J:$J,MATCH(1,('[1]PROSES ENJEKSİYON'!$A:$A=$T$2)*('[1]PROSES ENJEKSİYON'!$F:$F=A7),0)),"")} -> 2 | V7: {=IFERROR(INDEX('[1]PROSES ENJEKSİYON'!$K:$K,MATCH(1,('[1]PROSES ENJEKSİYON'!$A:$A=$T$2)*('[1]PROSES ENJEKSİYON'!$F:$F=A7),0)),"")} -> 2 | W7: {=IFERROR(INDEX('[1]PROSES ENJEKSİYON'!$L:$L,MATCH(1,('[1]PROSES ENJEKSİYON'!$A:$A=$T$2)*('[1]PROSES ENJEKSİYON'!$F:$F=A7),0)),"")} -> 22.51 | X7: {=IFERROR(INDEX('[1]PROSES ENJEKSİYON'!$G:$G,MATCH(1,('[1]PROSES ENJEKSİYON'!$A:$A=$X$2)*('[1]PROSES ENJEKSİYON'!$F:$F=A7),0)),"")} | Y7: {=IFERROR(INDEX('[1]PROSES ENJEKSİYON'!$J:$J,MATCH(1,('[1]PROSES ENJEKSİYON'!$A:$A=$X$2)*('[1]PROSES ENJEKSİYON'!$F:$F=A7),0)),"")} | Z7: {=IFERROR(INDEX('[1]PROSES ENJEKSİYON'!$K:$K,MATCH(1,('[1]PROSES ENJEKSİYON'!$A:$A=$X$2)*('[1]PROSES ENJEKSİYON'!$F:$F=A7),0)),"")} | AA7: {=IFERROR(INDEX('[1]PROSES ENJEKSİYON'!$L:$L,MATCH(1,('[1]PROSES ENJEKSİYON'!$A:$A=$X$2)*('[1]PROSES ENJEKSİYON'!$F:$F=A7),0)),"")} | AB7: {=IFERROR(INDEX('[1]PROSES ENJEKSİYON'!$G:$G,MATCH(1,('[1]PROSES ENJEKSİYON'!$A:$A=$AB$2)*('[1]PROSES ENJEKSİYON'!$F:$F=A7),0)),"")} | AC7: {=IFERROR(INDEX('[1]PROSES ENJEKSİYON'!$J:$J,MATCH(1,('[1]PROSES ENJEKSİYON'!$A:$A=$AB$2)*('[1]PROSES ENJEKSİYON'!$F:$F=M7),0)),"")} | AD7: {=IFERROR(INDEX('[1]PROSES ENJEKSİYON'!$K:$K,MATCH(1,('[1]PROSES ENJEKSİYON'!$A:$A=$AD$2)*('[1]PROSES ENJEKSİYON'!$F:$F=M7),0)),"")} | AE7: {=IFERROR(INDEX('[1]PROSES ENJEKSİYON'!$L:$L,MATCH(1,('[1]PROSES ENJEKSİYON'!$A:$A=$AB$2)*('[1]PROSES ENJEKSİYON'!$F:$F=A7),0)),"")}
A8: 162 | B8: {=IFERROR(INDEX('[1]PROSES ENJEKSİYON'!$L:$L, MATCH(1,('[1]PROSES ENJEKSİYON'!$A:$A=$B$2)*('[1]PROSES ENJEKSİYON'!$F:$F=A8),0)), "")} | C8: {=IFERROR(INDEX('[1]PROSES ENJEKSİYON'!$L:$L,MATCH(1,('[1]PROSES ENJEKSİYON'!$A:$A=$C$2)*('[1]PROSES ENJEKSİYON'!$F:$F=A8),0)),"")} | D8: {=IFERROR(INDEX('[1]PROSES ENJEKSİYON'!$L:$L,MATCH(1,('[1]PROSES ENJEKSİYON'!$A:$A=$D$2)*('[1]PROSES ENJEKSİYON'!$F:$F=A8),0)),"")} | E8: {=IFERROR(INDEX('[1]PROSES ENJEKSİYON'!$L:$L,MATCH(1,('[1]PROSES ENJEKSİYON'!$A:$A=$E$2)*('[1]PROSES ENJEKSİYON'!$F:$F=A8),0)),"")} | F8: {=IFERROR(INDEX('[1]PROSES ENJEKSİYON'!$L:$L,MATCH(1,('[1]PROSES ENJEKSİYON'!$A:$A=$F$2)*('[1]PROSES ENJEKSİYON'!$F:$F=A8),0)),"")} | G8: {=IFERROR(INDEX('[1]PROSES ENJEKSİYON'!$L:$L,MATCH(1,('[1]PROSES ENJEKSİYON'!$A:$A=$G$2)*('[1]PROSES ENJEKSİYON'!$F:$F=A8),0)),"")} | H8: {=IFERROR(INDEX('[1]PROSES ENJEKSİYON'!$G:$G,MATCH(1,('[1]PROSES ENJEKSİYON'!$A:$A=$H$2)*('[1]PROSES ENJEKSİYON'!$F:$F=A8),0)),"")} -> PET0014-01 1000ML SEFFAF SEFFAF 28MM YIVLI 52GR | I8: {=IFERROR(INDEX('[1]PROSES ENJEKSİYON'!$J:$J,MATCH(1,('[1]PROSES ENJEKSİYON'!$A:$A=$H$2)*('[1]PROSES ENJEKSİYON'!$F:$F=A8),0)),"")} -> 6 | J8: {=IFERROR(INDEX('[1]PROSES ENJEKSİYON'!$K:$K,MATCH(1,('[1]PROSES ENJEKSİYON'!$A:$A=$H$2)*('[1]PROSES ENJEKSİYON'!$F:$F=A8),0)),"")} -> 6 | K8: {=IFERROR(INDEX('[1]PROSES ENJEKSİYON'!$L:$L,MATCH(1,('[1]PROSES ENJEKSİYON'!$A:$A=$H$2)*('[1]PROSES ENJEKSİYON'!$F:$F=A8),0)),"")} -> 24 | L8: {=IFERROR(INDEX('[1]PROSES ENJEKSİYON'!$G:$G,MATCH(1,('[1]PROSES ENJEKSİYON'!$A:$A=$L$2)*('[1]PROSES ENJEKSİYON'!$F:$F=A8),0)),"")} | M8: {=IFERROR(INDEX('[1]PROSES ENJEKSİYON'!$J:$J,MATCH(1,('[1]PROSES ENJEKSİYON'!$A:$A=$L$2)*('[1]PROSES ENJEKSİYON'!$F:$F=A8),0)),"")} | N8: {=IFERROR(INDEX('[1]PROSES ENJEKSİYON'!$K:$K,MATCH(1,('[1]PROSES ENJEKSİYON'!$A:$A=$L$2)*('[1]PROSES ENJEKSİYON'!$F:$F=A8),0)),"")} | O8: {=IFERROR(INDEX('[1]PROSES ENJEKSİYON'!$L:$L,MATCH(1,('[1]PROSES ENJEKSİYON'!$A:$A=$L$2)*('[1]PROSES ENJEKSİYON'!$F:$F=A8),0)),"")} | P8: {=IFERROR(INDEX('[1]PROSES ENJEKSİYON'!$G:$G,MATCH(1,('[1]PROSES ENJEKSİYON'!$A:$A=$P$2)*('[1]PROSES ENJEKSİYON'!$F:$F=A8),0)),"")} -> MM-PET0013-02-028Y-052 - PET0013-02 1000ML OPAK BEYAZ 28MM YIVLI 52GR | Q8: {=IFERROR(INDEX('[1]PROSES ENJEKSİYON'!$J:$J,MATCH(1,('[1]PROSES ENJEKSİYON'!$A:$A=$P$2)*('[1]PROSES ENJEKSİYON'!$F:$F=A8),0)),"")} -> 2 | R8: {=IFERROR(INDEX('[1]PROSES ENJEKSİYON'!$K:$K,MATCH(1,('[1]PROSES ENJEKSİYON'!$A:$A=$P$2)*('[1]PROSES ENJEKSİYON'!$F:$F=A8),0)),"")} -> 2 | S8: {=IFERROR(INDEX('[1]PROSES ENJEKSİYON'!$L:$L,MATCH(1,('[1]PROSES ENJEKSİYON'!$A:$A=$P$2)*('[1]PROSES ENJEKSİYON'!$F:$F=A8),0)),"")} -> 24 | T8: {=IFERROR(INDEX('[1]PROSES ENJEKSİYON'!$G:$G,MATCH(1,('[1]PROSES ENJEKSİYON'!$A:$A=$T$2)*('[1]PROSES ENJEKSİYON'!$F:$F=A8),0)),"")} | U8: {=IFERROR(INDEX('[1]PROSES ENJEKSİYON'!$J:$J,MATCH(1,('[1]PROSES ENJEKSİYON'!$A:$A=$T$2)*('[1]PROSES ENJEKSİYON'!$F:$F=A8),0)),"")} | V8: {=IFERROR(INDEX('[1]PROSES ENJEKSİYON'!$K:$K,MATCH(1,('[1]PROSES ENJEKSİYON'!$A:$A=$T$2)*('[1]PROSES ENJEKSİYON'!$F:$F=A8),0)),"")} | W8: {=IFERROR(INDEX('[1]PROSES ENJEKSİYON'!$L:$L,MATCH(1,('[1]PROSES ENJEKSİYON'!$A:$A=$T$2)*('[1]PROSES ENJEKSİYON'!$F:$F=A8),0)),"")} | X8: {=IFERROR(INDEX('[1]PROSES ENJEKSİYON'!$G:$G,MATCH(1,('[1]PROSES ENJEKSİYON'!$A:$A=$X$2)*('[1]PROSES ENJEKSİYON'!$F:$F=A8),0)),"")} | Y8: {=IFERROR(INDEX('[1]PROSES ENJEKSİYON'!$J:$J,MATCH(1,('[1]PROSES ENJEKSİYON'!$A:$A=$X$2)*('[1]PROSES ENJEKSİYON'!$F:$F=A8),0)),"")} | Z8: {=IFERROR(INDEX('[1]PROSES ENJEKSİYON'!$K:$K,MATCH(1,('[1]PROSES ENJEKSİYON'!$A:$A=$X$2)*('[1]PROSES ENJEKSİYON'!$F:$F=A8),0)),"")} | AA8: {=IFERROR(INDEX('[1]PROSES ENJEKSİYON'!$L:$L,MATCH(1,('[1]PROSES ENJEKSİYON'!$A:$A=$X$2)*('[1]PROSES ENJEKSİYON'!$F:$F=A8),0)),"")} | AB8: {=IFERROR(INDEX('[1]PROSES ENJEKSİYON'!$G:$G,MATCH(1,('[1]PROSES ENJEKSİYON'!$A:$A=$AB$2)*('[1]PROSES ENJEKSİYON'!$F:$F=A8),0)),"")} | AC8: {=IFERROR(INDEX('[1]PROSES ENJEKSİYON'!$J:$J,MATCH(1,('[1]PROSES ENJEKSİYON'!$A:$A=$AB$2)*('[1]PROSES ENJEKSİYON'!$F:$F=M8),0)),"")} | AD8: {=IFERROR(INDEX('[1]PROSES ENJEKSİYON'!$K:$K,MATCH(1,('[1]PROSES ENJEKSİYON'!$A:$A=$AD$2)*('[1]PROSES ENJEKSİYON'!$F:$F=M8),0)),"")} | AE8: {=IFERROR(INDEX('[1]PROSES ENJEKSİYON'!$L:$L,MATCH(1,('[1]PROSES ENJEKSİYON'!$A:$A=$AB$2)*('[1]PROSES ENJEKSİYON'!$F:$F=A8),0)),"")}
A9: 163 | B9: {=IFERROR(INDEX('[1]PROSES ENJEKSİYON'!$L:$L, MATCH(1,('[1]PROSES ENJEKSİYON'!$A:$A=$B$2)*('[1]PROSES ENJEKSİYON'!$F:$F=A9),0)), "")} | C9: {=IFERROR(INDEX('[1]PROSES ENJEKSİYON'!$L:$L,MATCH(1,('[1]PROSES ENJEKSİYON'!$A:$A=$C$2)*('[1]PROSES ENJEKSİYON'!$F:$F=A9),0)),"")} | D9: {=IFERROR(INDEX('[1]PROSES ENJEKSİYON'!$L:$L,MATCH(1,('[1]PROSES ENJEKSİYON'!$A:$A=$D$2)*('[1]PROSES ENJEKSİYON'!$F:$F=A9),0)),"")} | E9: {=IFERROR(INDEX('[1]PROSES ENJEKSİYON'!$L:$L,MATCH(1,('[1]PROSES ENJEKSİYON'!$A:$A=$E$2)*('[1]PROSES ENJEKSİYON'!$F:$F=A9),0)),"")} | F9: {=IFERROR(INDEX('[1]PROSES ENJEKSİYON'!$L:$L,MATCH(1,('[1]PROSES ENJEKSİYON'!$A:$A=$F$2)*('[1]PROSES ENJEKSİYON'!$F:$F=A9),0)),"")} | G9: {=IFERROR(INDEX('[1]PROSES ENJEKSİYON'!$L:$L,MATCH(1,('[1]PROSES ENJEKSİYON'!$A:$A=$G$2)*('[1]PROSES ENJEKSİYON'!$F:$F=A9),0)),"")} | H9: {=IFERROR(INDEX('[1]PROSES ENJEKSİYON'!$G:$G,MATCH(1,('[1]PROSES ENJEKSİYON'!$A:$A=$H$2)*('[1]PROSES ENJEKSİYON'!$F:$F=A9),0)),"")} | I9: {=IFERROR(INDEX('[1]PROSES ENJEKSİYON'!$J:$J,MATCH(1,('[1]PROSES ENJEKSİYON'!$A:$A=$H$2)*('[1]PROSES ENJEKSİYON'!$F:$F=A9),0)),"")} | J9: {=IFERROR(INDEX('[1]PROSES ENJEKSİYON'!$K:$K,MATCH(1,('[1]PROSES ENJEKSİYON'!$A:$A=$H$2)*('[1]PROSES ENJEKSİYON'!$F:$F=A9),0)),"")} | K9: {=IFERROR(INDEX('[1]PROSES ENJEKSİYON'!$L:$L,MATCH(1,('[1]PROSES ENJEKSİYON'!$A:$A=$H$2)*('[1]PROSES ENJEKSİYON'!$F:$F=A9),0)),"")} | L9: {=IFERROR(INDEX('[1]PROSES ENJEKSİYON'!$G:$G,MATCH(1,('[1]PROSES ENJEKSİYON'!$A:$A=$L$2)*('[1]PROSES ENJEKSİYON'!$F:$F=A9),0)),"")} | M9: {=IFERROR(INDEX('[1]PROSES ENJEKSİYON'!$J:$J,MATCH(1,('[1]PROSES ENJEKSİYON'!$A:$A=$L$2)*('[1]PROSES ENJEKSİYON'!$F:$F=A9),0)),"")} | N9: {=IFERROR(INDEX('[1]PROSES ENJEKSİYON'!$K:$K,MATCH(1,('[1]PROSES ENJEKSİYON'!$A:$A=$L$2)*('[1]PROSES ENJEKSİYON'!$F:$F=A9),0)),"")} | O9: {=IFERROR(INDEX('[1]PROSES ENJEKSİYON'!$L:$L,MATCH(1,('[1]PROSES ENJEKSİYON'!$A:$A=$L$2)*('[1]PROSES ENJEKSİYON'!$F:$F=A9),0)),"")} | P9: {=IFERROR(INDEX('[1]PROSES ENJEKSİYON'!$G:$G,MATCH(1,('[1]PROSES ENJEKSİYON'!$A:$A=$P$2)*('[1]PROSES ENJEKSİYON'!$F:$F=A9),0)),"")} -> MM-PET0295-01-028Y-040 - PET0295-01 739ML SEFFAF SEFFAF 28MM YIVLI 40GR | Q9: {=IFERROR(INDEX('[1]PROSES ENJEKSİYON'!$J:$J,MATCH(1,('[1]PROSES ENJEKSİYON'!$A:$A=$P$2)*('[1]PROSES ENJEKSİYON'!$F:$F=A9),0)),"")} -> 2 | R9: {=IFERROR(INDEX('[1]PROSES ENJEKSİYON'!$K:$K,MATCH(1,('[1]PROSES ENJEKSİYON'!$A:$A=$P$2)*('[1]PROSES ENJEKSİYON'!$F:$F=A9),0)),"")} -> 2 | S9: {=IFERROR(INDEX('[1]PROSES ENJEKSİYON'!$L:$L,MATCH(1,('[1]PROSES ENJEKSİYON'!$A:$A=$P$2)*('[1]PROSES ENJEKSİYON'!$F:$F=A9),0)),"")} -> 0 | T9: {=IFERROR(INDEX('[1]PROSES ENJEKSİYON'!$G:$G,MATCH(1,('[1]PROSES ENJEKSİYON'!$A:$A=$T$2)*('[1]PROSES ENJEKSİYON'!$F:$F=A9),0)),"")} -> PET0295-01 739ML SEFFAF SEFFAF 28MM YIVLI 40GR | U9: {=IFERROR(INDEX('[1]PROSES ENJEKSİYON'!$J:$J,MATCH(1,('[1]PROSES ENJEKSİYON'!$A:$A=$T$2)*('[1]PROSES ENJEKSİYON'!$F:$F=A9),0)),"")} -> 2 | V9: {=IFERROR(INDEX('[1]PROSES ENJEKSİYON'!$K:$K,MATCH(1,('[1]PROSES ENJEKSİYON'!$A:$A=$T$2)*('[1]PROSES ENJEKSİYON'!$F:$F=A9),0)),"")} -> 2 | W9: {=IFERROR(INDEX('[1]PROSES ENJEKSİYON'!$L:$L,MATCH(1,('[1]PROSES ENJEKSİYON'!$A:$A=$T$2)*('[1]PROSES ENJEKSİYON'!$F:$F=A9),0)),"")} -> 19.79 | X9: {=IFERROR(INDEX('[1]PROSES ENJEKSİYON'!$G:$G,MATCH(1,('[1]PROSES ENJEKSİYON'!$A:$A=$X$2)*('[1]PROSES ENJEKSİYON'!$F:$F=A9),0)),"")} | Y9: {=IFERROR(INDEX('[1]PROSES ENJEKSİYON'!$J:$J,MATCH(1,('[1]PROSES ENJEKSİYON'!$A:$A=$X$2)*('[1]PROSES ENJEKSİYON'!$F:$F=A9),0)),"")} | Z9: {=IFERROR(INDEX('[1]PROSES ENJEKSİYON'!$K:$K,MATCH(1,('[1]PROSES ENJEKSİYON'!$A:$A=$X$2)*('[1]PROSES ENJEKSİYON'!$F:$F=A9),0)),"")} | AA9: {=IFERROR(INDEX('[1]PROSES ENJEKSİYON'!$L:$L,MATCH(1,('[1]PROSES ENJEKSİYON'!$A:$A=$X$2)*('[1]PROSES ENJEKSİYON'!$F:$F=A9),0)),"")} | AB9: {=IFERROR(INDEX('[1]PROSES ENJEKSİYON'!$G:$G,MATCH(1,('[1]PROSES ENJEKSİYON'!$A:$A=$AB$2)*('[1]PROSES ENJEKSİYON'!$F:$F=A9),0)),"")} | AC9: {=IFERROR(INDEX('[1]PROSES ENJEKSİYON'!$J:$J,MATCH(1,('[1]PROSES ENJEKSİYON'!$A:$A=$AB$2)*('[1]PROSES ENJEKSİYON'!$F:$F=M9),0)),"")} | AD9: {=IFERROR(INDEX('[1]PROSES ENJEKSİYON'!$K:$K,MATCH(1,('[1]PROSES ENJEKSİYON'!$A:$A=$AD$2)*('[1]PROSES ENJEKSİYON'!$F:$F=M9),0)),"")} | AE9: {=IFERROR(INDEX('[1]PROSES ENJEKSİYON'!$L:$L,MATCH(1,('[1]PROSES ENJEKSİYON'!$A:$A=$AB$2)*('[1]PROSES ENJEKSİYON'!$F:$F=A9),0)),"")}
A10: 164 | B10: {=IFERROR(INDEX('[1]PROSES ENJEKSİYON'!$L:$L, MATCH(1,('[1]PROSES ENJEKSİYON'!$A:$A=$B$2)*('[1]PROSES ENJEKSİYON'!$F:$F=A10),0)), "")} | C10: {=IFERROR(INDEX('[1]PROSES ENJEKSİYON'!$L:$L,MATCH(1,('[1]PROSES ENJEKSİYON'!$A:$A=$C$2)*('[1]PROSES ENJEKSİYON'!$F:$F=A10),0)),"")} | D10: {=IFERROR(INDEX('[1]PROSES ENJEKSİYON'!$L:$L,MATCH(1,('[1]PROSES ENJEKSİYON'!$A:$A=$D$2)*('[1]PROSES ENJEKSİYON'!$F:$F=A10),0)),"")} | E10: {=IFERROR(INDEX('[1]PROSES ENJEKSİYON'!$L:$L,MATCH(1,('[1]PROSES ENJEKSİYON'!$A:$A=$E$2)*('[1]PROSES ENJEKSİYON'!$F:$F=A10),0)),"")} | F10: {=IFERROR(INDEX('[1]PROSES ENJEKSİYON'!$L:$L,MATCH(1,('[1]PROSES ENJEKSİYON'!$A:$A=$F$2)*('[1]PROSES ENJEKSİYON'!$F:$F=A10),0)),"")} | G10: {=IFERROR(INDEX('[1]PROSES ENJEKSİYON'!$L:$L,MATCH(1,('[1]PROSES ENJEKSİYON'!$A:$A=$G$2)*('[1]PROSES ENJEKSİYON'!$F:$F=A10),0)),"")} | H10: {=IFERROR(INDEX('[1]PROSES ENJEKSİYON'!$G:$G,MATCH(1,('[1]PROSES ENJEKSİYON'!$A:$A=$H$2)*('[1]PROSES ENJEKSİYON'!$F:$F=A10),0)),"")} | I10: {=IFERROR(INDEX('[1]PROSES ENJEKSİYON'!$J:$J,MATCH(1,('[1]PROSES ENJEKSİYON'!$A:$A=$H$2)*('[1]PROSES ENJEKSİYON'!$F:$F=A10),0)),"")} | J10: {=IFERROR(INDEX('[1]PROSES ENJEKSİYON'!$K:$K,MATCH(1,('[1]PROSES ENJEKSİYON'!$A:$A=$H$2)*('[1]PROSES ENJEKSİYON'!$F:$F=A10),0)),"")} | K10: {=IFERROR(INDEX('[1]PROSES ENJEKSİYON'!$L:$L,MATCH(1,('[1]PROSES ENJEKSİYON'!$A:$A=$H$2)*('[1]PROSES ENJEKSİYON'!$F:$F=A10),0)),"")} | L10: {=IFERROR(INDEX('[1]PROSES ENJEKSİYON'!$G:$G,MATCH(1,('[1]PROSES ENJEKSİYON'!$A:$A=$L$2)*('[1]PROSES ENJEKSİYON'!$F:$F=A10),0)),"")} | M10: {=IFERROR(INDEX('[1]PROSES ENJEKSİYON'!$J:$J,MATCH(1,('[1]PROSES ENJEKSİYON'!$A:$A=$L$2)*('[1]PROSES ENJEKSİYON'!$F:$F=A10),0)),"")} | N10: {=IFERROR(INDEX('[1]PROSES ENJEKSİYON'!$K:$K,MATCH(1,('[1]PROSES ENJEKSİYON'!$A:$A=$L$2)*('[1]PROSES ENJEKSİYON'!$F:$F=A10),0)),"")} | O10: {=IFERROR(INDEX('[1]PROSES ENJEKSİYON'!$L:$L,MATCH(1,('[1]PROSES ENJEKSİYON'!$A:$A=$L$2)*('[1]PROSES ENJEKSİYON'!$F:$F=A10),0)),"")} | P10: {=IFERROR(INDEX('[1]PROSES ENJEKSİYON'!$G:$G,MATCH(1,('[1]PROSES ENJEKSİYON'!$A:$A=$P$2)*('[1]PROSES ENJEKSİYON'!$F:$F=A10),0)),"")} -> MM-PET0014-01-028Y-052 - PET0014-01 1000ML SEFFAF SEFFAF 28MM YIVLI 52GR | Q10: {=IFERROR(INDEX('[1]PROSES ENJEKSİYON'!$J:$J,MATCH(1,('[1]PROSES ENJEKSİYON'!$A:$A=$P$2)*('[1]PROSES ENJEKSİYON'!$F:$F=A10),0)),"")} -> 2 | R10: {=IFERROR(INDEX('[1]PROSES ENJEKSİYON'!$K:$K,MATCH(1,('[1]PROSES ENJEKSİYON'!$A:$A=$P$2)*('[1]PROSES ENJEKSİYON'!$F:$F=A10),0)),"")} -> 2 | S10: {=IFERROR(INDEX('[1]PROSES ENJEKSİYON'!$L:$L,MATCH(1,('[1]PROSES ENJEKSİYON'!$A:$A=$P$2)*('[1]PROSES ENJEKSİYON'!$F:$F=A10),0)),"")} -> 23.99 | T10: {=IFERROR(INDEX('[1]PROSES ENJEKSİYON'!$G:$G,MATCH(1,('[1]PROSES ENJEKSİYON'!$A:$A=$T$2)*('[1]PROSES ENJEKSİYON'!$F:$F=A10),0)),"")} | U10: {=IFERROR(INDEX('[1]PROSES ENJEKSİYON'!$J:$J,MATCH(1,('[1]PROSES ENJEKSİYON'!$A:$A=$T$2)*('[1]PROSES ENJEKSİYON'!$F:$F=A10),0)),"")} | V10: {=IFERROR(INDEX('[1]PROSES ENJEKSİYON'!$K:$K,MATCH(1,('[1]PROSES ENJEKSİYON'!$A:$A=$T$2)*('[1]PROSES ENJEKSİYON'!$F:$F=A10),0)),"")} | W10: {=IFERROR(INDEX('[1]PROSES ENJEKSİYON'!$L:$L,MATCH(1,('[1]PROSES ENJEKSİYON'!$A:$A=$T$2)*('[1]PROSES ENJEKSİYON'!$F:$F=A10),0)),"")} | X10: {=IFERROR(INDEX('[1]PROSES ENJEKSİYON'!$G:$G,MATCH(1,('[1]PROSES ENJEKSİYON'!$A:$A=$X$2)*('[1]PROSES ENJEKSİYON'!$F:$F=A10),0)),"")} | Y10: {=IFERROR(INDEX('[1]PROSES ENJEKSİYON'!$J:$J,MATCH(1,('[1]PROSES ENJEKSİYON'!$A:$A=$X$2)*('[1]PROSES ENJEKSİYON'!$F:$F=A10),0)),"")} | Z10: {=IFERROR(INDEX('[1]PROSES ENJEKSİYON'!$K:$K,MATCH(1,('[1]PROSES ENJEKSİYON'!$A:$A=$X$2)*('[1]PROSES ENJEKSİYON'!$F:$F=A10),0)),"")} | AA10: {=IFERROR(INDEX('[1]PROSES ENJEKSİYON'!$L:$L,MATCH(1,('[1]PROSES ENJEKSİYON'!$A:$A=$X$2)*('[1]PROSES ENJEKSİYON'!$F:$F=A10),0)),"")} | AB10: {=IFERROR(INDEX('[1]PROSES ENJEKSİYON'!$G:$G,MATCH(1,('[1]PROSES ENJEKSİYON'!$A:$A=$AB$2)*('[1]PROSES ENJEKSİYON'!$F:$F=A10),0)),"")} | AC10: {=IFERROR(INDEX('[1]PROSES ENJEKSİYON'!$J:$J,MATCH(1,('[1]PROSES ENJEKSİYON'!$A:$A=$AB$2)*('[1]PROSES ENJEKSİYON'!$F:$F=M10),0)),"")} | AD10: {=IFERROR(INDEX('[1]PROSES ENJEKSİYON'!$K:$K,MATCH(1,('[1]PROSES ENJEKSİYON'!$A:$A=$AD$2)*('[1]PROSES ENJEKSİYON'!$F:$F=M10),0)),"")} | AE10: {=IFERROR(INDEX('[1]PROSES ENJEKSİYON'!$L:$L,MATCH(1,('[1]PROSES ENJEKSİYON'!$A:$A=$AB$2)*('[1]PROSES ENJEKSİYON'!$F:$F=A10),0)),"")}
A11: 181 | B11: {=IFERROR(INDEX('[1]PROSES ENJEKSİYON'!$L:$L, MATCH(1,('[1]PROSES ENJEKSİYON'!$A:$A=$B$2)*('[1]PROSES ENJEKSİYON'!$F:$F=A11),0)), "")} | C11: {=IFERROR(INDEX('[1]PROSES ENJEKSİYON'!$L:$L,MATCH(1,('[1]PROSES ENJEKSİYON'!$A:$A=$C$2)*('[1]PROSES ENJEKSİYON'!$F:$F=A11),0)),"")} | D11: {=IFERROR(INDEX('[1]PROSES ENJEKSİYON'!$L:$L,MATCH(1,('[1]PROSES ENJEKSİYON'!$A:$A=$D$2)*('[1]PROSES ENJEKSİYON'!$F:$F=A11),0)),"")} | E11: {=IFERROR(INDEX('[1]PROSES ENJEKSİYON'!$L:$L,MATCH(1,('[1]PROSES ENJEKSİYON'!$A:$A=$E$2)*('[1]PROSES ENJEKSİYON'!$F:$F=A11),0)),"")} | F11: {=IFERROR(INDEX('[1]PROSES ENJEKSİYON'!$L:$L,MATCH(1,('[1]PROSES ENJEKSİYON'!$A:$A=$F$2)*('[1]PROSES ENJEKSİYON'!$F:$F=A11),0)),"")} | G11: {=IFERROR(INDEX('[1]PROSES ENJEKSİYON'!$L:$L,MATCH(1,('[1]PROSES ENJEKSİYON'!$A:$A=$G$2)*('[1]PROSES ENJEKSİYON'!$F:$F=A11),0)),"")} | H11: {=IFERROR(INDEX('[1]PROSES ENJEKSİYON'!$G:$G,MATCH(1,('[1]PROSES ENJEKSİYON'!$A:$A=$H$2)*('[1]PROSES ENJEKSİYON'!$F:$F=A11),0)),"")} | I11: {=IFERROR(INDEX('[1]PROSES ENJEKSİYON'!$J:$J,MATCH(1,('[1]PROSES ENJEKSİYON'!$A:$A=$H$2)*('[1]PROSES ENJEKSİYON'!$F:$F=A11),0)),"")} | J11: {=IFERROR(INDEX('[1]PROSES ENJEKSİYON'!$K:$K,MATCH(1,('[1]PROSES ENJEKSİYON'!$A:$A=$H$2)*('[1]PROSES ENJEKSİYON'!$F:$F=A11),0)),"")} | K11: {=IFERROR(INDEX('[1]PROSES ENJEKSİYON'!$L:$L,MATCH(1,('[1]PROSES ENJEKSİYON'!$A:$A=$H$2)*('[1]PROSES ENJEKSİYON'!$F:$F=A11),0)),"")} | L11: {=IFERROR(INDEX('[1]PROSES ENJEKSİYON'!$G:$G,MATCH(1,('[1]PROSES ENJEKSİYON'!$A:$A=$L$2)*('[1]PROSES ENJEKSİYON'!$F:$F=A11),0)),"")} | M11: {=IFERROR(INDEX('[1]PROSES ENJEKSİYON'!$J:$J,MATCH(1,('[1]PROSES ENJEKSİYON'!$A:$A=$L$2)*('[1]PROSES ENJEKSİYON'!$F:$F=A11),0)),"")} | N11: {=IFERROR(INDEX('[1]PROSES ENJEKSİYON'!$K:$K,MATCH(1,('[1]PROSES ENJEKSİYON'!$A:$A=$L$2)*('[1]PROSES ENJEKSİYON'!$F:$F=A11),0)),"")} | O11: {=IFERROR(INDEX('[1]PROSES ENJEKSİYON'!$L:$L,MATCH(1,('[1]PROSES ENJEKSİYON'!$A:$A=$L$2)*('[1]PROSES ENJEKSİYON'!$F:$F=A11),0)),"")} | P11: {=IFERROR(INDEX('[1]PROSES ENJEKSİYON'!$G:$G,MATCH(1,('[1]PROSES ENJEKSİYON'!$A:$A=$P$2)*('[1]PROSES ENJEKSİYON'!$F:$F=A11),0)),"")} | Q11: {=IFERROR(INDEX('[1]PROSES ENJEKSİYON'!$J:$J,MATCH(1,('[1]PROSES ENJEKSİYON'!$A:$A=$P$2)*('[1]PROSES ENJEKSİYON'!$F:$F=A11),0)),"")} | R11: {=IFERROR(INDEX('[1]PROSES ENJEKSİYON'!$K:$K,MATCH(1,('[1]PROSES ENJEKSİYON'!$A:$A=$P$2)*('[1]PROSES ENJEKSİYON'!$F:$F=A11),0)),"")} | S11: {=IFERROR(INDEX('[1]PROSES ENJEKSİYON'!$L:$L,MATCH(1,('[1]PROSES ENJEKSİYON'!$A:$A=$P$2)*('[1]PROSES ENJEKSİYON'!$F:$F=A11),0)),"")} | T11: {=IFERROR(INDEX('[1]PROSES ENJEKSİYON'!$G:$G,MATCH(1,('[1]PROSES ENJEKSİYON'!$A:$A=$T$2)*('[1]PROSES ENJEKSİYON'!$F:$F=A11),0)),"")} | U11: {=IFERROR(INDEX('[1]PROSES ENJEKSİYON'!$J:$J,MATCH(1,('[1]PROSES ENJEKSİYON'!$A:$A=$T$2)*('[1]PROSES ENJEKSİYON'!$F:$F=A11),0)),"")} | V11: {=IFERROR(INDEX('[1]PROSES ENJEKSİYON'!$K:$K,MATCH(1,('[1]PROSES ENJEKSİYON'!$A:$A=$T$2)*('[1]PROSES ENJEKSİYON'!$F:$F=A11),0)),"")} | W11: {=IFERROR(INDEX('[1]PROSES ENJEKSİYON'!$L:$L,MATCH(1,('[1]PROSES ENJEKSİYON'!$A:$A=$T$2)*('[1]PROSES ENJEKSİYON'!$F:$F=A11),0)),"")} | X11: {=IFERROR(INDEX('[1]PROSES ENJEKSİYON'!$G:$G,MATCH(1,('[1]PROSES ENJEKSİYON'!$A:$A=$X$2)*('[1]PROSES ENJEKSİYON'!$F:$F=A11),0)),"")} | Y11: {=IFERROR(INDEX('[1]PROSES ENJEKSİYON'!$J:$J,MATCH(1,('[1]PROSES ENJEKSİYON'!$A:$A=$X$2)*('[1]PROSES ENJEKSİYON'!$F:$F=A11),0)),"")} | Z11: {=IFERROR(INDEX('[1]PROSES ENJEKSİYON'!$K:$K,MATCH(1,('[1]PROSES ENJEKSİYON'!$A:$A=$X$2)*('[1]PROSES ENJEKSİYON'!$F:$F=A11),0)),"")} | AA11: {=IFERROR(INDEX('[1]PROSES ENJEKSİYON'!$L:$L,MATCH(1,('[1]PROSES ENJEKSİYON'!$A:$A=$X$2)*('[1]PROSES ENJEKSİYON'!$F:$F=A11),0)),"")} | AB11: {=IFERROR(INDEX('[1]PROSES ENJEKSİYON'!$G:$G,MATCH(1,('[1]PROSES ENJEKSİYON'!$A:$A=$AB$2)*('[1]PROSES ENJEKSİYON'!$F:$F=A11),0)),"")} | AC11: {=IFERROR(INDEX('[1]PROSES ENJEKSİYON'!$J:$J,MATCH(1,('[1]PROSES ENJEKSİYON'!$A:$A=$AB$2)*('[1]PROSES ENJEKSİYON'!$F:$F=M11),0)),"")} | AD11: {=IFERROR(INDEX('[1]PROSES ENJEKSİYON'!$K:$K,MATCH(1,('[1]PROSES ENJEKSİYON'!$A:$A=$AD$2)*('[1]PROSES ENJEKSİYON'!$F:$F=M11),0)),"")} | AE11: {=IFERROR(INDEX('[1]PROSES ENJEKSİYON'!$L:$L,MATCH(1,('[1]PROSES ENJEKSİYON'!$A:$A=$AB$2)*('[1]PROSES ENJEKSİYON'!$F:$F=A11),0)),"")}
A12: 182 | B12: {=IFERROR(INDEX('[1]PROSES ENJEKSİYON'!$L:$L, MATCH(1,('[1]PROSES ENJEKSİYON'!$A:$A=$B$2)*('[1]PROSES ENJEKSİYON'!$F:$F=A12),0)), "")} | C12: {=IFERROR(INDEX('[1]PROSES ENJEKSİYON'!$L:$L,MATCH(1,('[1]PROSES ENJEKSİYON'!$A:$A=$C$2)*('[1]PROSES ENJEKSİYON'!$F:$F=A12),0)),"")} | D12: {=IFERROR(INDEX('[1]PROSES ENJEKSİYON'!$L:$L,MATCH(1,('[1]PROSES ENJEKSİYON'!$A:$A=$D$2)*('[1]PROSES ENJEKSİYON'!$F:$F=A12),0)),"")} | E12: {=IFERROR(INDEX('[1]PROSES ENJEKSİYON'!$L:$L,MATCH(1,('[1]PROSES ENJEKSİYON'!$A:$A=$E$2)*('[1]PROSES ENJEKSİYON'!$F:$F=A12),0)),"")} | F12: {=IFERROR(INDEX('[1]PROSES ENJEKSİYON'!$L:$L,MATCH(1,('[1]PROSES ENJEKSİYON'!$A:$A=$F$2)*('[1]PROSES ENJEKSİYON'!$F:$F=A12),0)),"")} | G12: {=IFERROR(INDEX('[1]PROSES ENJEKSİYON'!$L:$L,MATCH(1,('[1]PROSES ENJEKSİYON'!$A:$A=$G$2)*('[1]PROSES ENJEKSİYON'!$F:$F=A12),0)),"")} | H12: {=IFERROR(INDEX('[1]PROSES ENJEKSİYON'!$G:$G,MATCH(1,('[1]PROSES ENJEKSİYON'!$A:$A=$H$2)*('[1]PROSES ENJEKSİYON'!$F:$F=A12),0)),"")} | I12: {=IFERROR(INDEX('[1]PROSES ENJEKSİYON'!$J:$J,MATCH(1,('[1]PROSES ENJEKSİYON'!$A:$A=$H$2)*('[1]PROSES ENJEKSİYON'!$F:$F=A12),0)),"")} | J12: {=IFERROR(INDEX('[1]PROSES ENJEKSİYON'!$K:$K,MATCH(1,('[1]PROSES ENJEKSİYON'!$A:$A=$H$2)*('[1]PROSES ENJEKSİYON'!$F:$F=A12),0)),"")} | K12: {=IFERROR(INDEX('[1]PROSES ENJEKSİYON'!$L:$L,MATCH(1,('[1]PROSES ENJEKSİYON'!$A:$A=$H$2)*('[1]PROSES ENJEKSİYON'!$F:$F=A12),0)),"")} | L12: {=IFERROR(INDEX('[1]PROSES ENJEKSİYON'!$G:$G,MATCH(1,('[1]PROSES ENJEKSİYON'!$A:$A=$L$2)*('[1]PROSES ENJEKSİYON'!$F:$F=A12),0)),"")} | M12: {=IFERROR(INDEX('[1]PROSES ENJEKSİYON'!$J:$J,MATCH(1,('[1]PROSES ENJEKSİYON'!$A:$A=$L$2)*('[1]PROSES ENJEKSİYON'!$F:$F=A12),0)),"")} | N12: {=IFERROR(INDEX('[1]PROSES ENJEKSİYON'!$K:$K,MATCH(1,('[1]PROSES ENJEKSİYON'!$A:$A=$L$2)*('[1]PROSES ENJEKSİYON'!$F:$F=A12),0)),"")} | O12: {=IFERROR(INDEX('[1]PROSES ENJEKSİYON'!$L:$L,MATCH(1,('[1]PROSES ENJEKSİYON'!$A:$A=$L$2)*('[1]PROSES ENJEKSİYON'!$F:$F=A12),0)),"")} | P12: {=IFERROR(INDEX('[1]PROSES ENJEKSİYON'!$G:$G,MATCH(1,('[1]PROSES ENJEKSİYON'!$A:$A=$P$2)*('[1]PROSES ENJEKSİYON'!$F:$F=A12),0)),"")} -> MM-PET0170-01-028Y-026 - PET0170-01 400ML SEFFAF YESIL 28MM YIVLI 26GR | Q12: {=IFERROR(INDEX('[1]PROSES ENJEKSİYON'!$J:$J,MATCH(1,('[1]PROSES ENJEKSİYON'!$A:$A=$P$2)*('[1]PROSES ENJEKSİYON'!$F:$F=A12),0)),"")} -> 4 | R12: {=IFERROR(INDEX('[1]PROSES ENJEKSİYON'!$K:$K,MATCH(1,('[1]PROSES ENJEKSİYON'!$A:$A=$P$2)*('[1]PROSES ENJEKSİYON'!$F:$F=A12),0)),"")} -> 4 | S12: {=IFERROR(INDEX('[1]PROSES ENJEKSİYON'!$L:$L,MATCH(1,('[1]PROSES ENJEKSİYON'!$A:$A=$P$2)*('[1]PROSES ENJEKSİYON'!$F:$F=A12),0)),"")} -> 14.05 | T12: {=IFERROR(INDEX('[1]PROSES ENJEKSİYON'!$G:$G,MATCH(1,('[1]PROSES ENJEKSİYON'!$A:$A=$T$2)*('[1]PROSES ENJEKSİYON'!$F:$F=A12),0)),"")} -> PET0170-01 400ML SEFFAF YESIL 28MM YIVLI 26GR | U12: {=IFERROR(INDEX('[1]PROSES ENJEKSİYON'!$J:$J,MATCH(1,('[1]PROSES ENJEKSİYON'!$A:$A=$T$2)*('[1]PROSES ENJEKSİYON'!$F:$F=A12),0)),"")} -> 4 | V12: {=IFERROR(INDEX('[1]PROSES ENJEKSİYON'!$K:$K,MATCH(1,('[1]PROSES ENJEKSİYON'!$A:$A=$T$2)*('[1]PROSES ENJEKSİYON'!$F:$F=A12),0)),"")} -> 4 | W12: {=IFERROR(INDEX('[1]PROSES ENJEKSİYON'!$L:$L,MATCH(1,('[1]PROSES ENJEKSİYON'!$A:$A=$T$2)*('[1]PROSES ENJEKSİYON'!$F:$F=A12),0)),"")} -> 14.05 | X12: {=IFERROR(INDEX('[1]PROSES ENJEKSİYON'!$G:$G,MATCH(1,('[1]PROSES ENJEKSİYON'!$A:$A=$X$2)*('[1]PROSES ENJEKSİYON'!$F:$F=A12),0)),"")} | Y12: {=IFERROR(INDEX('[1]PROSES ENJEKSİYON'!$J:$J,MATCH(1,('[1]PROSES ENJEKSİYON'!$A:$A=$X$2)*('[1]PROSES ENJEKSİYON'!$F:$F=A12),0)),"")} | Z12: {=IFERROR(INDEX('[1]PROSES ENJEKSİYON'!$K:$K,MATCH(1,('[1]PROSES ENJEKSİYON'!$A:$A=$X$2)*('[1]PROSES ENJEKSİYON'!$F:$F=A12),0)),"")} | AA12: {=IFERROR(INDEX('[1]PROSES ENJEKSİYON'!$L:$L,MATCH(1,('[1]PROSES ENJEKSİYON'!$A:$A=$X$2)*('[1]PROSES ENJEKSİYON'!$F:$F=A12),0)),"")} | AB12: {=IFERROR(INDEX('[1]PROSES ENJEKSİYON'!$G:$G,MATCH(1,('[1]PROSES ENJEKSİYON'!$A:$A=$AB$2)*('[1]PROSES ENJEKSİYON'!$F:$F=A12),0)),"")} | AC12: {=IFERROR(INDEX('[1]PROSES ENJEKSİYON'!$J:$J,MATCH(1,('[1]PROSES ENJEKSİYON'!$A:$A=$AB$2)*('[1]PROSES ENJEKSİYON'!$F:$F=M12),0)),"")} | AD12: {=IFERROR(INDEX('[1]PROSES ENJEKSİYON'!$K:$K,MATCH(1,('[1]PROSES ENJEKSİYON'!$A:$A=$AD$2)*('[1]PROSES ENJEKSİYON'!$F:$F=M12),0)),"")} | AE12: {=IFERROR(INDEX('[1]PROSES ENJEKSİYON'!$L:$L,MATCH(1,('[1]PROSES ENJEKSİYON'!$A:$A=$AB$2)*('[1]PROSES ENJEKSİYON'!$F:$F=A12),0)),"")}
A13: 401 | B13: {=IFERROR(INDEX('[1]PROSES ENJEKSİYON'!$L:$L, MATCH(1,('[1]PROSES ENJEKSİYON'!$A:$A=$B$2)*('[1]PROSES ENJEKSİYON'!$F:$F=A13),0)), "")} | C13: {=IFERROR(INDEX('[1]PROSES ENJEKSİYON'!$L:$L,MATCH(1,('[1]PROSES ENJEKSİYON'!$A:$A=$C$2)*('[1]PROSES ENJEKSİYON'!$F:$F=A13),0)),"")} -> 10.09 | D13: {=IFERROR(INDEX('[1]PROSES ENJEKSİYON'!$L:$L,MATCH(1,('[1]PROSES ENJEKSİYON'!$A:$A=$D$2)*('[1]PROSES ENJEKSİYON'!$F:$F=A13),0)),"")} | E13: {=IFERROR(INDEX('[1]PROSES ENJEKSİYON'!$L:$L,MATCH(1,('[1]PROSES ENJEKSİYON'!$A:$A=$E$2)*('[1]PROSES ENJEKSİYON'!$F:$F=A13),0)),"")} | F13: {=IFERROR(INDEX('[1]PROSES ENJEKSİYON'!$L:$L,MATCH(1,('[1]PROSES ENJEKSİYON'!$A:$A=$F$2)*('[1]PROSES ENJEKSİYON'!$F:$F=A13),0)),"")} | G13: {=IFERROR(INDEX('[1]PROSES ENJEKSİYON'!$L:$L,MATCH(1,('[1]PROSES ENJEKSİYON'!$A:$A=$G$2)*('[1]PROSES ENJEKSİYON'!$F:$F=A13),0)),"")} -> 8.3 | H13: {=IFERROR(INDEX('[1]PROSES ENJEKSİYON'!$G:$G,MATCH(1,('[1]PROSES ENJEKSİYON'!$A:$A=$H$2)*('[1]PROSES ENJEKSİYON'!$F:$F=A13),0)),"")} | I13: {=IFERROR(INDEX('[1]PROSES ENJEKSİYON'!$J:$J,MATCH(1,('[1]PROSES ENJEKSİYON'!$A:$A=$H$2)*('[1]PROSES ENJEKSİYON'!$F:$F=A13),0)),"")} | J13: {=IFERROR(INDEX('[1]PROSES ENJEKSİYON'!$K:$K,MATCH(1,('[1]PROSES ENJEKSİYON'!$A:$A=$H$2)*('[1]PROSES ENJEKSİYON'!$F:$F=A13),0)),"")} | K13: {=IFERROR(INDEX('[1]PROSES ENJEKSİYON'!$L:$L,MATCH(1,('[1]PROSES ENJEKSİYON'!$A:$A=$H$2)*('[1]PROSES ENJEKSİYON'!$F:$F=A13),0)),"")} | L13: {=IFERROR(INDEX('[1]PROSES ENJEKSİYON'!$G:$G,MATCH(1,('[1]PROSES ENJEKSİYON'!$A:$A=$L$2)*('[1]PROSES ENJEKSİYON'!$F:$F=A13),0)),"")} | M13: {=IFERROR(INDEX('[1]PROSES ENJEKSİYON'!$J:$J,MATCH(1,('[1]PROSES ENJEKSİYON'!$A:$A=$L$2)*('[1]PROSES ENJEKSİYON'!$F:$F=A13),0)),"")} | N13: {=IFERROR(INDEX('[1]PROSES ENJEKSİYON'!$K:$K,MATCH(1,('[1]PROSES ENJEKSİYON'!$A:$A=$L$2)*('[1]PROSES ENJEKSİYON'!$F:$F=A13),0)),"")} | O13: {=IFERROR(INDEX('[1]PROSES ENJEKSİYON'!$L:$L,MATCH(1,('[1]PROSES ENJEKSİYON'!$A:$A=$L$2)*('[1]PROSES ENJEKSİYON'!$F:$F=A13),0)),"")} | P13: {=IFERROR(INDEX('[1]PROSES ENJEKSİYON'!$G:$G,MATCH(1,('[1]PROSES ENJEKSİYON'!$A:$A=$P$2)*('[1]PROSES ENJEKSİYON'!$F:$F=A13),0)),"")} | Q13: {=IFERROR(INDEX('[1]PROSES ENJEKSİYON'!$J:$J,MATCH(1,('[1]PROSES ENJEKSİYON'!$A:$A=$P$2)*('[1]PROSES ENJEKSİYON'!$F:$F=A13),0)),"")} | R13: {=IFERROR(INDEX('[1]PROSES ENJEKSİYON'!$K:$K,MATCH(1,('[1]PROSES ENJEKSİYON'!$A:$A=$P$2)*('[1]PROSES ENJEKSİYON'!$F:$F=A13),0)),"")} | S13: {=IFERROR(INDEX('[1]PROSES ENJEKSİYON'!$L:$L,MATCH(1,('[1]PROSES ENJEKSİYON'!$A:$A=$P$2)*('[1]PROSES ENJEKSİYON'!$F:$F=A13),0)),"")} | T13: {=IFERROR(INDEX('[1]PROSES ENJEKSİYON'!$G:$G,MATCH(1,('[1]PROSES ENJEKSİYON'!$A:$A=$T$2)*('[1]PROSES ENJEKSİYON'!$F:$F=A13),0)),"")} | U13: {=IFERROR(INDEX('[1]PROSES ENJEKSİYON'!$J:$J,MATCH(1,('[1]PROSES ENJEKSİYON'!$A:$A=$T$2)*('[1]PROSES ENJEKSİYON'!$F:$F=A13),0)),"")} | V13: {=IFERROR(INDEX('[1]PROSES ENJEKSİYON'!$K:$K,MATCH(1,('[1]PROSES ENJEKSİYON'!$A:$A=$T$2)*('[1]PROSES ENJEKSİYON'!$F:$F=A13),0)),"")} | W13: {=IFERROR(INDEX('[1]PROSES ENJEKSİYON'!$L:$L,MATCH(1,('[1]PROSES ENJEKSİYON'!$A:$A=$T$2)*('[1]PROSES ENJEKSİYON'!$F:$F=A13),0)),"")} | X13: {=IFERROR(INDEX('[1]PROSES ENJEKSİYON'!$G:$G,MATCH(1,('[1]PROSES ENJEKSİYON'!$A:$A=$X$2)*('[1]PROSES ENJEKSİYON'!$F:$F=A13),0)),"")} | Y13: {=IFERROR(INDEX('[1]PROSES ENJEKSİYON'!$J:$J,MATCH(1,('[1]PROSES ENJEKSİYON'!$A:$A=$X$2)*('[1]PROSES ENJEKSİYON'!$F:$F=A13),0)),"")} | Z13: {=IFERROR(INDEX('[1]PROSES ENJEKSİYON'!$K:$K,MATCH(1,('[1]PROSES ENJEKSİYON'!$A:$A=$X$2)*('[1]PROSES ENJEKSİYON'!$F:$F=A13),0)),"")} | AA13: {=IFERROR(INDEX('[1]PROSES ENJEKSİYON'!$L:$L,MATCH(1,('[1]PROSES ENJEKSİYON'!$A:$A=$X$2)*('[1]PROSES ENJEKSİYON'!$F:$F=A13),0)),"")} | AB13: {=IFERROR(INDEX('[1]PROSES ENJEKSİYON'!$G:$G,MATCH(1,('[1]PROSES ENJEKSİYON'!$A:$A=$AB$2)*('[1]PROSES ENJEKSİYON'!$F:$F=A13),0)),"")} | AC13: {=IFERROR(INDEX('[1]PROSES ENJEKSİYON'!$J:$J,MATCH(1,('[1]PROSES ENJEKSİYON'!$A:$A=$AB$2)*('[1]PROSES ENJEKSİYON'!$F:$F=M13),0)),"")} | AD13: {=IFERROR(INDEX('[1]PROSES ENJEKSİYON'!$K:$K,MATCH(1,('[1]PROSES ENJEKSİYON'!$A:$A=$AD$2)*('[1]PROSES ENJEKSİYON'!$F:$F=M13),0)),"")} | AE13: {=IFERROR(INDEX('[1]PROSES ENJEKSİYON'!$L:$L,MATCH(1,('[1]PROSES ENJEKSİYON'!$A:$A=$AB$2)*('[1]PROSES ENJEKSİYON'!$F:$F=A13),0)),"")}
A14: 402 | B14: {=IFERROR(INDEX('[1]PROSES ENJEKSİYON'!$L:$L, MATCH(1,('[1]PROSES ENJEKSİYON'!$A:$A=$B$2)*('[1]PROSES ENJEKSİYON'!$F:$F=A14),0)), "")} | C14: {=IFERROR(INDEX('[1]PROSES ENJEKSİYON'!$L:$L,MATCH(1,('[1]PROSES ENJEKSİYON'!$A:$A=$C$2)*('[1]PROSES ENJEKSİYON'!$F:$F=A14),0)),"")} | D14: {=IFERROR(INDEX('[1]PROSES ENJEKSİYON'!$L:$L,MATCH(1,('[1]PROSES ENJEKSİYON'!$A:$A=$D$2)*('[1]PROSES ENJEKSİYON'!$F:$F=A14),0)),"")} | E14: {=IFERROR(INDEX('[1]PROSES ENJEKSİYON'!$L:$L,MATCH(1,('[1]PROSES ENJEKSİYON'!$A:$A=$E$2)*('[1]PROSES ENJEKSİYON'!$F:$F=A14),0)),"")} | F14: {=IFERROR(INDEX('[1]PROSES ENJEKSİYON'!$L:$L,MATCH(1,('[1]PROSES ENJEKSİYON'!$A:$A=$F$2)*('[1]PROSES ENJEKSİYON'!$F:$F=A14),0)),"")} | G14: {=IFERROR(INDEX('[1]PROSES ENJEKSİYON'!$L:$L,MATCH(1,('[1]PROSES ENJEKSİYON'!$A:$A=$G$2)*('[1]PROSES ENJEKSİYON'!$F:$F=A14),0)),"")} | H14: {=IFERROR(INDEX('[1]PROSES ENJEKSİYON'!$G:$G,MATCH(1,('[1]PROSES ENJEKSİYON'!$A:$A=$H$2)*('[1]PROSES ENJEKSİYON'!$F:$F=A14),0)),"")} -> BLW0011-01 1500ML OPAK BEYAZ 38MM YIVLI 74GR | I14: {=IFERROR(INDEX('[1]PROSES ENJEKSİYON'!$J:$J,MATCH(1,('[1]PROSES ENJEKSİYON'!$A:$A=$H$2)*('[1]PROSES ENJEKSİYON'!$F:$F=A14),0)),"")} -> 2 | J14: {=IFERROR(INDEX('[1]PROSES ENJEKSİYON'!$K:$K,MATCH(1,('[1]PROSES ENJEKSİYON'!$A:$A=$H$2)*('[1]PROSES ENJEKSİYON'!$F:$F=A14),0)),"")} -> 2 | K14: {=IFERROR(INDEX('[1]PROSES ENJEKSİYON'!$L:$L,MATCH(1,('[1]PROSES ENJEKSİYON'!$A:$A=$H$2)*('[1]PROSES ENJEKSİYON'!$F:$F=A14),0)),"")} -> 8.5 | L14: {=IFERROR(INDEX('[1]PROSES ENJEKSİYON'!$G:$G,MATCH(1,('[1]PROSES ENJEKSİYON'!$A:$A=$L$2)*('[1]PROSES ENJEKSİYON'!$F:$F=A14),0)),"")} | M14: {=IFERROR(INDEX('[1]PROSES ENJEKSİYON'!$J:$J,MATCH(1,('[1]PROSES ENJEKSİYON'!$A:$A=$L$2)*('[1]PROSES ENJEKSİYON'!$F:$F=A14),0)),"")} | N14: {=IFERROR(INDEX('[1]PROSES ENJEKSİYON'!$K:$K,MATCH(1,('[1]PROSES ENJEKSİYON'!$A:$A=$L$2)*('[1]PROSES ENJEKSİYON'!$F:$F=A14),0)),"")} | O14: {=IFERROR(INDEX('[1]PROSES ENJEKSİYON'!$L:$L,MATCH(1,('[1]PROSES ENJEKSİYON'!$A:$A=$L$2)*('[1]PROSES ENJEKSİYON'!$F:$F=A14),0)),"")} | P14: {=IFERROR(INDEX('[1]PROSES ENJEKSİYON'!$G:$G,MATCH(1,('[1]PROSES ENJEKSİYON'!$A:$A=$P$2)*('[1]PROSES ENJEKSİYON'!$F:$F=A14),0)),"")} | Q14: {=IFERROR(INDEX('[1]PROSES ENJEKSİYON'!$J:$J,MATCH(1,('[1]PROSES ENJEKSİYON'!$A:$A=$P$2)*('[1]PROSES ENJEKSİYON'!$F:$F=A14),0)),"")} | R14: {=IFERROR(INDEX('[1]PROSES ENJEKSİYON'!$K:$K,MATCH(1,('[1]PROSES ENJEKSİYON'!$A:$A=$P$2)*('[1]PROSES ENJEKSİYON'!$F:$F=A14),0)),"")} | S14: {=IFERROR(INDEX('[1]PROSES ENJEKSİYON'!$L:$L,MATCH(1,('[1]PROSES ENJEKSİYON'!$A:$A=$P$2)*('[1]PROSES ENJEKSİYON'!$F:$F=A14),0)),"")} | T14: {=IFERROR(INDEX('[1]PROSES ENJEKSİYON'!$G:$G,MATCH(1,('[1]PROSES ENJEKSİYON'!$A:$A=$T$2)*('[1]PROSES ENJEKSİYON'!$F:$F=A14),0)),"")} | U14: {=IFERROR(INDEX('[1]PROSES ENJEKSİYON'!$J:$J,MATCH(1,('[1]PROSES ENJEKSİYON'!$A:$A=$T$2)*('[1]PROSES ENJEKSİYON'!$F:$F=A14),0)),"")} | V14: {=IFERROR(INDEX('[1]PROSES ENJEKSİYON'!$K:$K,MATCH(1,('[1]PROSES ENJEKSİYON'!$A:$A=$T$2)*('[1]PROSES ENJEKSİYON'!$F:$F=A14),0)),"")} | W14: {=IFERROR(INDEX('[1]PROSES ENJEKSİYON'!$L:$L,MATCH(1,('[1]PROSES ENJEKSİYON'!$A:$A=$T$2)*('[1]PROSES ENJEKSİYON'!$F:$F=A14),0)),"")} | X14: {=IFERROR(INDEX('[1]PROSES ENJEKSİYON'!$G:$G,MATCH(1,('[1]PROSES ENJEKSİYON'!$A:$A=$X$2)*('[1]PROSES ENJEKSİYON'!$F:$F=A14),0)),"")} | Y14: {=IFERROR(INDEX('[1]PROSES ENJEKSİYON'!$J:$J,MATCH(1,('[1]PROSES ENJEKSİYON'!$A:$A=$X$2)*('[1]PROSES ENJEKSİYON'!$F:$F=A14),0)),"")} | Z14: {=IFERROR(INDEX('[1]PROSES ENJEKSİYON'!$K:$K,MATCH(1,('[1]PROSES ENJEKSİYON'!$A:$A=$X$2)*('[1]PROSES ENJEKSİYON'!$F:$F=A14),0)),"")} | AA14: {=IFERROR(INDEX('[1]PROSES ENJEKSİYON'!$L:$L,MATCH(1,('[1]PROSES ENJEKSİYON'!$A:$A=$X$2)*('[1]PROSES ENJEKSİYON'!$F:$F=A14),0)),"")} | AB14: {=IFERROR(INDEX('[1]PROSES ENJEKSİYON'!$G:$G,MATCH(1,('[1]PROSES ENJEKSİYON'!$A:$A=$AB$2)*('[1]PROSES ENJEKSİYON'!$F:$F=A14),0)),"")} | AC14: {=IFERROR(INDEX('[1]PROSES ENJEKSİYON'!$J:$J,MATCH(1,('[1]PROSES ENJEKSİYON'!$A:$A=$AB$2)*('[1]PROSES ENJEKSİYON'!$F:$F=M14),0)),"")} | AD14: {=IFERROR(INDEX('[1]PROSES ENJEKSİYON'!$K:$K,MATCH(1,('[1]PROSES ENJEKSİYON'!$A:$A=$AD$2)*('[1]PROSES ENJEKSİYON'!$F:$F=M14),0)),"")} | AE14: {=IFERROR(INDEX('[1]PROSES ENJEKSİYON'!$L:$L,MATCH(1,('[1]PROSES ENJEKSİYON'!$A:$A=$AB$2)*('[1]PROSES ENJEKSİYON'!$F:$F=A14),0)),"")}
... A47: 502 | B47: {=IFERROR(INDEX('[1]PROSES ENJEKSİYON'!$L:$L, MATCH(1,('[1]PROSES ENJEKSİYON'!$A:$A=$B$2)*('[1]PROSES ENJEKSİYON'!$F:$F=A47),0)), "")} | C47: {=IFERROR(INDEX('[1]PROSES ENJEKSİYON'!$L:$L,MATCH(1,('[1]PROSES ENJEKSİYON'!$A:$A=$C$2)*('[1]PROSES ENJEKSİYON'!$F:$F=A47),0)),"")} | D47: {=IFERROR(INDEX('[1]PROSES ENJEKSİYON'!$L:$L,MATCH(1,('[1]PROSES ENJEKSİYON'!$A:$A=$D$2)*('[1]PROSES ENJEKSİYON'!$F:$F=A47),0)),"")} | E47: {=IFERROR(INDEX('[1]PROSES ENJEKSİYON'!$L:$L,MATCH(1,('[1]PROSES ENJEKSİYON'!$A:$A=$E$2)*('[1]PROSES ENJEKSİYON'!$F:$F=A47),0)),"")} | F47: {=IFERROR(INDEX('[1]PROSES ENJEKSİYON'!$L:$L,MATCH(1,('[1]PROSES ENJEKSİYON'!$A:$A=$F$2)*('[1]PROSES ENJEKSİYON'!$F:$F=A47),0)),"")} | G47: {=IFERROR(INDEX('[1]PROSES ENJEKSİYON'!$L:$L,MATCH(1,('[1]PROSES ENJEKSİYON'!$A:$A=$G$2)*('[1]PROSES ENJEKSİYON'!$F:$F=A47),0)),"")} | H47: {=IFERROR(INDEX('[1]PROSES ENJEKSİYON'!$G:$G,MATCH(1,('[1]PROSES ENJEKSİYON'!$A:$A=$H$2)*('[1]PROSES ENJEKSİYON'!$F:$F=A47),0)),"")} -> EBM0006-01 265ML OPAK BEYAZ 38MM YIVLI 30GR | I47: {=IFERROR(INDEX('[1]PROSES ENJEKSİYON'!$J:$J,MATCH(1,('[1]PROSES ENJEKSİYON'!$A:$A=$H$2)*('[1]PROSES ENJEKSİYON'!$F:$F=A47),0)),"")} -> 0 | J47: {=IFERROR(INDEX('[1]PROSES ENJEKSİYON'!$K:$K,MATCH(1,('[1]PROSES ENJEKSİYON'!$A:$A=$H$2)*('[1]PROSES ENJEKSİYON'!$F:$F=A47),0)),"")} -> 0 | K47: {=IFERROR(INDEX('[1]PROSES ENJEKSİYON'!$L:$L,MATCH(1,('[1]PROSES ENJEKSİYON'!$A:$A=$H$2)*('[1]PROSES ENJEKSİYON'!$F:$F=A47),0)),"")} -> 0 | L47: {=IFERROR(INDEX('[1]PROSES ENJEKSİYON'!$G:$G,MATCH(1,('[1]PROSES ENJEKSİYON'!$A:$A=$L$2)*('[1]PROSES ENJEKSİYON'!$F:$F=A47),0)),"")} | M47: {=IFERROR(INDEX('[1]PROSES ENJEKSİYON'!$J:$J,MATCH(1,('[1]PROSES ENJEKSİYON'!$A:$A=$L$2)*('[1]PROSES ENJEKSİYON'!$F:$F=A47),0)),"")} | N47: {=IFERROR(INDEX('[1]PROSES ENJEKSİYON'!$K:$K,MATCH(1,('[1]PROSES ENJEKSİYON'!$A:$A=$L$2)*('[1]PROSES ENJEKSİYON'!$F:$F=A47),0)),"")} | O47: {=IFERROR(INDEX('[1]PROSES ENJEKSİYON'!$L:$L,MATCH(1,('[1]PROSES ENJEKSİYON'!$A:$A=$L$2)*('[1]PROSES ENJEKSİYON'!$F:$F=A47),0)),"")} | P47: {=IFERROR(INDEX('[1]PROSES ENJEKSİYON'!$G:$G,MATCH(1,('[1]PROSES ENJEKSİYON'!$A:$A=$P$2)*('[1]PROSES ENJEKSİYON'!$F:$F=A47),0)),"")} | Q47: {=IFERROR(INDEX('[1]PROSES ENJEKSİYON'!$J:$J,MATCH(1,('[1]PROSES ENJEKSİYON'!$A:$A=$P$2)*('[1]PROSES ENJEKSİYON'!$F:$F=A47),0)),"")} | R47: {=IFERROR(INDEX('[1]PROSES ENJEKSİYON'!$K:$K,MATCH(1,('[1]PROSES ENJEKSİYON'!$A:$A=$P$2)*('[1]PROSES ENJEKSİYON'!$F:$F=A47),0)),"")} | S47: {=IFERROR(INDEX('[1]PROSES ENJEKSİYON'!$L:$L,MATCH(1,('[1]PROSES ENJEKSİYON'!$A:$A=$P$2)*('[1]PROSES ENJEKSİYON'!$F:$F=A47),0)),"")} | T47: {=IFERROR(INDEX('[1]PROSES ENJEKSİYON'!$G:$G,MATCH(1,('[1]PROSES ENJEKSİYON'!$A:$A=$T$2)*('[1]PROSES ENJEKSİYON'!$F:$F=A47),0)),"")} | U47: {=IFERROR(INDEX('[1]PROSES ENJEKSİYON'!$J:$J,MATCH(1,('[1]PROSES ENJEKSİYON'!$A:$A=$T$2)*('[1]PROSES ENJEKSİYON'!$F:$F=A47),0)),"")} | V47: {=IFERROR(INDEX('[1]PROSES ENJEKSİYON'!$K:$K,MATCH(1,('[1]PROSES ENJEKSİYON'!$A:$A=$T$2)*('[1]PROSES ENJEKSİYON'!$F:$F=A47),0)),"")} | W47: {=IFERROR(INDEX('[1]PROSES ENJEKSİYON'!$L:$L,MATCH(1,('[1]PROSES ENJEKSİYON'!$A:$A=$T$2)*('[1]PROSES ENJEKSİYON'!$F:$F=A47),0)),"")} | X47: {=IFERROR(INDEX('[1]PROSES ENJEKSİYON'!$G:$G,MATCH(1,('[1]PROSES ENJEKSİYON'!$A:$A=$X$2)*('[1]PROSES ENJEKSİYON'!$F:$F=A47),0)),"")} | Y47: {=IFERROR(INDEX('[1]PROSES ENJEKSİYON'!$J:$J,MATCH(1,('[1]PROSES ENJEKSİYON'!$A:$A=$X$2)*('[1]PROSES ENJEKSİYON'!$F:$F=A47),0)),"")} | Z47: {=IFERROR(INDEX('[1]PROSES ENJEKSİYON'!$K:$K,MATCH(1,('[1]PROSES ENJEKSİYON'!$A:$A=$X$2)*('[1]PROSES ENJEKSİYON'!$F:$F=A47),0)),"")} | AA47: {=IFERROR(INDEX('[1]PROSES ENJEKSİYON'!$L:$L,MATCH(1,('[1]PROSES ENJEKSİYON'!$A:$A=$X$2)*('[1]PROSES ENJEKSİYON'!$F:$F=A47),0)),"")} | AB47: {=IFERROR(INDEX('[1]PROSES ENJEKSİYON'!$G:$G,MATCH(1,('[1]PROSES ENJEKSİYON'!$A:$A=$AB$2)*('[1]PROSES ENJEKSİYON'!$F:$F=A47),0)),"")} | AC47: {=IFERROR(INDEX('[1]PROSES ENJEKSİYON'!$J:$J,MATCH(1,('[1]PROSES ENJEKSİYON'!$A:$A=$AB$2)*('[1]PROSES ENJEKSİYON'!$F:$F=M47),0)),"")} | AD47: {=IFERROR(INDEX('[1]PROSES ENJEKSİYON'!$K:$K,MATCH(1,('[1]PROSES ENJEKSİYON'!$A:$A=$AD$2)*('[1]PROSES ENJEKSİYON'!$F:$F=M47),0)),"")} | AE47: {=IFERROR(INDEX('[1]PROSES ENJEKSİYON'!$L:$L,MATCH(1,('[1]PROSES ENJEKSİYON'!$A:$A=$AB$2)*('[1]PROSES ENJEKSİYON'!$F:$F=A47),0)),"")}
H49: PAZARTESİ | L49: SALI | P49: ÇARŞAMBA | T49: PERŞEMBE | X49: CUMA | AB49: CUMARTESİ
A50: Makine Adı | B50: 45936 | C50: 45937 | D50: 45938 | E50: 45939 | F50: 45940 | G50: 45941 | H50: 46020 | I50: Toplam Göz Sayısı (ad) | J50: Çalışan Göz Sayısı (ad) | K50: Çevrim Süresi (sn) | L50: 46007 | M50: Toplam Göz Sayısı (ad) | N50: Çalışan Göz Sayısı (ad) | O50: Çevrim Süresi (sn) | P50: 46008 | Q50: Toplam Göz Sayısı (ad) | R50: Çalışan Göz Sayısı (ad) | S50: Çevrim Süresi (sn) | T50: 46009 | U50: Toplam Göz Sayısı (ad) | V50: Çalışan Göz Sayısı (ad) | W50: Çevrim Süresi (sn) | X50: 46010 | Y50: Toplam Göz Sayısı (ad) | Z50: Çalışan Göz Sayısı (ad) | AA50: Çevrim Süresi (sn) | AB50: 46011 | AC50: Toplam Göz Sayısı (ad) | AD50: Çalışan Göz Sayısı (ad) | AE50: Çevrim Süresi (sn)
